Workbook

Sheet Графики
A1: iPA-64-F (R086W2-2)
A2: 28 В, 0,65 А, Pвх=17 дБм, Н.Р.
A4: Частота, Гц | B4: Частота, ГГц | C4: Pвых, Вт | K4: Pвых, дБм | S4: Id, А | AA4: Ig, мА | AI4: Ку, дБ | AQ4: КПД, %
C5: №1 | D5: NiPA-62-F_UG_1__2026-03-24_11-4 | E5: NiPA-62-F_UG_2__2026-03-24_11-5 | F5: NiPA-62-F_UG_3__2026-03-24_13-0 | G5: NiPA-62-F_UG_4__2026-03-24_13-1 | H5: NiPA-62-F_UG_5__2026-03-24_13-2 | I5: NiPA-62-F_UG_6__2026-03-24_13-2 | J5: NiPA-62-F_UG_7__2026-03-24_13-3 | K5: =C5 | L5: =D5 | M5: =E5 | N5: =F5 | O5: =G5 | P5: =H5 | Q5: =I5 | R5: =J5 | S5: =C5 | T5: =D5 | U5: =E5 | V5: =F5 | W5: =G5 | X5: =H5 | Y5: =I5 | Z5: =J5 | AA5: =C5 | AB5: =D5 | AC5: =E5 | AD5: =F5 | AE5: =G5 | AF5: =H5 | AG5: =I5 | AH5: =J5 | AI5: =C5 | AJ5: =D5 | AK5: =E5 | AL5: =F5 | AM5: =G5 | AN5: =H5 | AO5: =I5 | AP5: =J5 | AQ5: =C5 | AR5: =D5 | AS5: =E5 | AT5: =F5 | AU5: =G5 | AV5: =H5 | AW5: =I5 | AX5: =J5
A6: ='NiPA-62-F_UG_7__2026-03-24_13-3'!B11 | B6: =A6/1000000000 | C6: =№1!U11 | D6: ='NiPA-62-F_UG_1__2026-03-24_11-4'!U11 | E6: ='NiPA-62-F_UG_2__2026-03-24_11-5'!U11 | F6: ='NiPA-62-F_UG_3__2026-03-24_13-0'!U11 | G6: ='NiPA-62-F_UG_4__2026-03-24_13-1'!U11 | H6: ='NiPA-62-F_UG_5__2026-03-24_13-2'!U11 | I6: ='NiPA-62-F_UG_6__2026-03-24_13-2'!U11 | J6: ='NiPA-62-F_UG_7__2026-03-24_13-3'!U11 | K6: =№1!P11 | L6: ='NiPA-62-F_UG_1__2026-03-24_11-4'!P11 | M6: ='NiPA-62-F_UG_2__2026-03-24_11-5'!P11 | N6: ='NiPA-62-F_UG_3__2026-03-24_13-0'!P11 | O6: ='NiPA-62-F_UG_4__2026-03-24_13-1'!P11 | P6: ='NiPA-62-F_UG_5__2026-03-24_13-2'!P11 | Q6: ='NiPA-62-F_UG_6__2026-03-24_13-2'!P11 | R6: ='NiPA-62-F_UG_7__2026-03-24_13-3'!P11 | S6: =№1!R11 | T6: ='NiPA-62-F_UG_1__2026-03-24_11-4'!R11 | U6: ='NiPA-62-F_UG_2__2026-03-24_11-5'!R11 | V6: ='NiPA-62-F_UG_3__2026-03-24_13-0'!R11 | W6: ='NiPA-62-F_UG_4__2026-03-24_13-1'!R11 | X6: ='NiPA-62-F_UG_5__2026-03-24_13-2'!R11 | Y6: ='NiPA-62-F_UG_6__2026-03-24_13-2'!R11 | Z6: ='NiPA-62-F_UG_7__2026-03-24_13-3'!R11 | AA6: =№1!Q11 | AB6: ='NiPA-62-F_UG_1__2026-03-24_11-4'!Q11 | AC6: ='NiPA-62-F_UG_2__2026-03-24_11-5'!Q11 | AD6: ='NiPA-62-F_UG_3__2026-03-24_13-0'!Q11 | AE6: ='NiPA-62-F_UG_4__2026-03-24_13-1'!Q11 | AF6: ='NiPA-62-F_UG_5__2026-03-24_13-2'!Q11 | AG6: ='NiPA-62-F_UG_6__2026-03-24_13-2'!Q11 | AH6: ='NiPA-62-F_UG_7__2026-03-24_13-3'!Q11 | AI6: =№1!S11 | AJ6: ='NiPA-62-F_UG_1__2026-03-24_11-4'!S11 | AK6: ='NiPA-62-F_UG_2__2026-03-24_11-5'!S11 | AL6: ='NiPA-62-F_UG_3__2026-03-24_13-0'!S11 | AM6: ='NiPA-62-F_UG_4__2026-03-24_13-1'!S11 | AN6: ='NiPA-62-F_UG_5__2026-03-24_13-2'!S11 | AO6: ='NiPA-62-F_UG_6__2026-03-24_13-2'!S11 | AP6: ='NiPA-62-F_UG_7__2026-03-24_13-3'!S11 | AQ6: =№1!T11 | AR6: ='NiPA-62-F_UG_1__2026-03-24_11-4'!T11 | AS6: ='NiPA-62-F_UG_2__2026-03-24_11-5'!T11 | AT6: ='NiPA-62-F_UG_3__2026-03-24_13-0'!T11 | AU6: ='NiPA-62-F_UG_4__2026-03-24_13-1'!T11 | AV6: ='NiPA-62-F_UG_5__2026-03-24_13-2'!T11 | AW6: ='NiPA-62-F_UG_6__2026-03-24_13-2'!T11 | AX6: ='NiPA-62-F_UG_7__2026-03-24_13-3'!T11
A7: ='NiPA-62-F_UG_7__2026-03-24_13-3'!B12 | B7: =A7/1000000000 | C7: =№1!U12 | D7: ='NiPA-62-F_UG_1__2026-03-24_11-4'!U12 | E7: ='NiPA-62-F_UG_2__2026-03-24_11-5'!U12 | F7: ='NiPA-62-F_UG_3__2026-03-24_13-0'!U12 | G7: ='NiPA-62-F_UG_4__2026-03-24_13-1'!U12 | H7: ='NiPA-62-F_UG_5__2026-03-24_13-2'!U12 | I7: ='NiPA-62-F_UG_6__2026-03-24_13-2'!U12 | J7: ='NiPA-62-F_UG_7__2026-03-24_13-3'!U12 | K7: =№1!P12 | L7: ='NiPA-62-F_UG_1__2026-03-24_11-4'!P12 | M7: ='NiPA-62-F_UG_2__2026-03-24_11-5'!P12 | N7: ='NiPA-62-F_UG_3__2026-03-24_13-0'!P12 | O7: ='NiPA-62-F_UG_4__2026-03-24_13-1'!P12 | P7: ='NiPA-62-F_UG_5__2026-03-24_13-2'!P12 | Q7: ='NiPA-62-F_UG_6__2026-03-24_13-2'!P12 | R7: ='NiPA-62-F_UG_7__2026-03-24_13-3'!P12 | S7: =№1!R12 | T7: ='NiPA-62-F_UG_1__2026-03-24_11-4'!R12 | U7: ='NiPA-62-F_UG_2__2026-03-24_11-5'!R12 | V7: ='NiPA-62-F_UG_3__2026-03-24_13-0'!R12 | W7: ='NiPA-62-F_UG_4__2026-03-24_13-1'!R12 | X7: ='NiPA-62-F_UG_5__2026-03-24_13-2'!R12 | Y7: ='NiPA-62-F_UG_6__2026-03-24_13-2'!R12 | Z7: ='NiPA-62-F_UG_7__2026-03-24_13-3'!R12 | AA7: =№1!Q12 | AB7: ='NiPA-62-F_UG_1__2026-03-24_11-4'!Q12 | AC7: ='NiPA-62-F_UG_2__2026-03-24_11-5'!Q12 | AD7: ='NiPA-62-F_UG_3__2026-03-24_13-0'!Q12 | AE7: ='NiPA-62-F_UG_4__2026-03-24_13-1'!Q12 | AF7: ='NiPA-62-F_UG_5__2026-03-24_13-2'!Q12 | AG7: ='NiPA-62-F_UG_6__2026-03-24_13-2'!Q12 | AH7: ='NiPA-62-F_UG_7__2026-03-24_13-3'!Q12 | AI7: =№1!S12 | AJ7: ='NiPA-62-F_UG_1__2026-03-24_11-4'!S12 | AK7: ='NiPA-62-F_UG_2__2026-03-24_11-5'!S12 | AL7: ='NiPA-62-F_UG_3__2026-03-24_13-0'!S12 | AM7: ='NiPA-62-F_UG_4__2026-03-24_13-1'!S12 | AN7: ='NiPA-62-F_UG_5__2026-03-24_13-2'!S12 | AO7: ='NiPA-62-F_UG_6__2026-03-24_13-2'!S12 | AP7: ='NiPA-62-F_UG_7__2026-03-24_13-3'!S12 | AQ7: =№1!T12 | AR7: ='NiPA-62-F_UG_1__2026-03-24_11-4'!T12 | AS7: ='NiPA-62-F_UG_2__2026-03-24_11-5'!T12 | AT7: ='NiPA-62-F_UG_3__2026-03-24_13-0'!T12 | AU7: ='NiPA-62-F_UG_4__2026-03-24_13-1'!T12 | AV7: ='NiPA-62-F_UG_5__2026-03-24_13-2'!T12 | AW7: ='NiPA-62-F_UG_6__2026-03-24_13-2'!T12 | AX7: ='NiPA-62-F_UG_7__2026-03-24_13-3'!T12
A8: ='NiPA-62-F_UG_7__2026-03-24_13-3'!B13 | B8: =A8/1000000000 | C8: =№1!U13 | D8: ='NiPA-62-F_UG_1__2026-03-24_11-4'!U13 | E8: ='NiPA-62-F_UG_2__2026-03-24_11-5'!U13 | F8: ='NiPA-62-F_UG_3__2026-03-24_13-0'!U13 | G8: ='NiPA-62-F_UG_4__2026-03-24_13-1'!U13 | H8: ='NiPA-62-F_UG_5__2026-03-24_13-2'!U13 | I8: ='NiPA-62-F_UG_6__2026-03-24_13-2'!U13 | J8: ='NiPA-62-F_UG_7__2026-03-24_13-3'!U13 | K8: =№1!P13 | L8: ='NiPA-62-F_UG_1__2026-03-24_11-4'!P13 | M8: ='NiPA-62-F_UG_2__2026-03-24_11-5'!P13 | N8: ='NiPA-62-F_UG_3__2026-03-24_13-0'!P13 | O8: ='NiPA-62-F_UG_4__2026-03-24_13-1'!P13 | P8: ='NiPA-62-F_UG_5__2026-03-24_13-2'!P13 | Q8: ='NiPA-62-F_UG_6__2026-03-24_13-2'!P13 | R8: ='NiPA-62-F_UG_7__2026-03-24_13-3'!P13 | S8: =№1!R13 | T8: ='NiPA-62-F_UG_1__2026-03-24_11-4'!R13 | U8: ='NiPA-62-F_UG_2__2026-03-24_11-5'!R13 | V8: ='NiPA-62-F_UG_3__2026-03-24_13-0'!R13 | W8: ='NiPA-62-F_UG_4__2026-03-24_13-1'!R13 | X8: ='NiPA-62-F_UG_5__2026-03-24_13-2'!R13 | Y8: ='NiPA-62-F_UG_6__2026-03-24_13-2'!R13 | Z8: ='NiPA-62-F_UG_7__2026-03-24_13-3'!R13 | AA8: =№1!Q13 | AB8: ='NiPA-62-F_UG_1__2026-03-24_11-4'!Q13 | AC8: ='NiPA-62-F_UG_2__2026-03-24_11-5'!Q13 | AD8: ='NiPA-62-F_UG_3__2026-03-24_13-0'!Q13 | AE8: ='NiPA-62-F_UG_4__2026-03-24_13-1'!Q13 | AF8: ='NiPA-62-F_UG_5__2026-03-24_13-2'!Q13 | AG8: ='NiPA-62-F_UG_6__2026-03-24_13-2'!Q13 | AH8: ='NiPA-62-F_UG_7__2026-03-24_13-3'!Q13 | AI8: =№1!S13 | AJ8: ='NiPA-62-F_UG_1__2026-03-24_11-4'!S13 | AK8: ='NiPA-62-F_UG_2__2026-03-24_11-5'!S13 | AL8: ='NiPA-62-F_UG_3__2026-03-24_13-0'!S13 | AM8: ='NiPA-62-F_UG_4__2026-03-24_13-1'!S13 | AN8: ='NiPA-62-F_UG_5__2026-03-24_13-2'!S13 | AO8: ='NiPA-62-F_UG_6__2026-03-24_13-2'!S13 | AP8: ='NiPA-62-F_UG_7__2026-03-24_13-3'!S13 | AQ8: =№1!T13 | AR8: ='NiPA-62-F_UG_1__2026-03-24_11-4'!T13 | AS8: ='NiPA-62-F_UG_2__2026-03-24_11-5'!T13 | AT8: ='NiPA-62-F_UG_3__2026-03-24_13-0'!T13 | AU8: ='NiPA-62-F_UG_4__2026-03-24_13-1'!T13 | AV8: ='NiPA-62-F_UG_5__2026-03-24_13-2'!T13 | AW8: ='NiPA-62-F_UG_6__2026-03-24_13-2'!T13 | AX8: ='NiPA-62-F_UG_7__2026-03-24_13-3'!T13
A9: ='NiPA-62-F_UG_7__2026-03-24_13-3'!B14 | B9: =A9/1000000000 | C9: =№1!U14 | D9: ='NiPA-62-F_UG_1__2026-03-24_11-4'!U14 | E9: ='NiPA-62-F_UG_2__2026-03-24_11-5'!U14 | F9: ='NiPA-62-F_UG_3__2026-03-24_13-0'!U14 | G9: ='NiPA-62-F_UG_4__2026-03-24_13-1'!U14 | H9: ='NiPA-62-F_UG_5__2026-03-24_13-2'!U14 | I9: ='NiPA-62-F_UG_6__2026-03-24_13-2'!U14 | J9: ='NiPA-62-F_UG_7__2026-03-24_13-3'!U14 | K9: =№1!P14 | L9: ='NiPA-62-F_UG_1__2026-03-24_11-4'!P14 | M9: ='NiPA-62-F_UG_2__2026-03-24_11-5'!P14 | N9: ='NiPA-62-F_UG_3__2026-03-24_13-0'!P14 | O9: ='NiPA-62-F_UG_4__2026-03-24_13-1'!P14 | P9: ='NiPA-62-F_UG_5__2026-03-24_13-2'!P14 | Q9: ='NiPA-62-F_UG_6__2026-03-24_13-2'!P14 | R9: ='NiPA-62-F_UG_7__2026-03-24_13-3'!P14 | S9: =№1!R14 | T9: ='NiPA-62-F_UG_1__2026-03-24_11-4'!R14 | U9: ='NiPA-62-F_UG_2__2026-03-24_11-5'!R14 | V9: ='NiPA-62-F_UG_3__2026-03-24_13-0'!R14 | W9: ='NiPA-62-F_UG_4__2026-03-24_13-1'!R14 | X9: ='NiPA-62-F_UG_5__2026-03-24_13-2'!R14 | Y9: ='NiPA-62-F_UG_6__2026-03-24_13-2'!R14 | Z9: ='NiPA-62-F_UG_7__2026-03-24_13-3'!R14 | AA9: =№1!Q14 | AB9: ='NiPA-62-F_UG_1__2026-03-24_11-4'!Q14 | AC9: ='NiPA-62-F_UG_2__2026-03-24_11-5'!Q14 | AD9: ='NiPA-62-F_UG_3__2026-03-24_13-0'!Q14 | AE9: ='NiPA-62-F_UG_4__2026-03-24_13-1'!Q14 | AF9: ='NiPA-62-F_UG_5__2026-03-24_13-2'!Q14 | AG9: ='NiPA-62-F_UG_6__2026-03-24_13-2'!Q14 | AH9: ='NiPA-62-F_UG_7__2026-03-24_13-3'!Q14 | AI9: =№1!S14 | AJ9: ='NiPA-62-F_UG_1__2026-03-24_11-4'!S14 | AK9: ='NiPA-62-F_UG_2__2026-03-24_11-5'!S14 | AL9: ='NiPA-62-F_UG_3__2026-03-24_13-0'!S14 | AM9: ='NiPA-62-F_UG_4__2026-03-24_13-1'!S14 | AN9: ='NiPA-62-F_UG_5__2026-03-24_13-2'!S14 | AO9: ='NiPA-62-F_UG_6__2026-03-24_13-2'!S14 | AP9: ='NiPA-62-F_UG_7__2026-03-24_13-3'!S14 | AQ9: =№1!T14 | AR9: ='NiPA-62-F_UG_1__2026-03-24_11-4'!T14 | AS9: ='NiPA-62-F_UG_2__2026-03-24_11-5'!T14 | AT9: ='NiPA-62-F_UG_3__2026-03-24_13-0'!T14 | AU9: ='NiPA-62-F_UG_4__2026-03-24_13-1'!T14 | AV9: ='NiPA-62-F_UG_5__2026-03-24_13-2'!T14 | AW9: ='NiPA-62-F_UG_6__2026-03-24_13-2'!T14 | AX9: ='NiPA-62-F_UG_7__2026-03-24_13-3'!T14
A10: ='NiPA-62-F_UG_7__2026-03-24_13-3'!B15 | B10: =A10/1000000000 | C10: =№1!U15 | D10: ='NiPA-62-F_UG_1__2026-03-24_11-4'!U15 | E10: ='NiPA-62-F_UG_2__2026-03-24_11-5'!U15 | F10: ='NiPA-62-F_UG_3__2026-03-24_13-0'!U15 | G10: ='NiPA-62-F_UG_4__2026-03-24_13-1'!U15 | H10: ='NiPA-62-F_UG_5__2026-03-24_13-2'!U15 | I10: ='NiPA-62-F_UG_6__2026-03-24_13-2'!U15 | J10: ='NiPA-62-F_UG_7__2026-03-24_13-3'!U15 | K10: =№1!P15 | L10: ='NiPA-62-F_UG_1__2026-03-24_11-4'!P15 | M10: ='NiPA-62-F_UG_2__2026-03-24_11-5'!P15 | N10: ='NiPA-62-F_UG_3__2026-03-24_13-0'!P15 | O10: ='NiPA-62-F_UG_4__2026-03-24_13-1'!P15 | P10: ='NiPA-62-F_UG_5__2026-03-24_13-2'!P15 | Q10: ='NiPA-62-F_UG_6__2026-03-24_13-2'!P15 | R10: ='NiPA-62-F_UG_7__2026-03-24_13-3'!P15 | S10: =№1!R15 | T10: ='NiPA-62-F_UG_1__2026-03-24_11-4'!R15 | U10: ='NiPA-62-F_UG_2__2026-03-24_11-5'!R15 | V10: ='NiPA-62-F_UG_3__2026-03-24_13-0'!R15 | W10: ='NiPA-62-F_UG_4__2026-03-24_13-1'!R15 | X10: ='NiPA-62-F_UG_5__2026-03-24_13-2'!R15 | Y10: ='NiPA-62-F_UG_6__2026-03-24_13-2'!R15 | Z10: ='NiPA-62-F_UG_7__2026-03-24_13-3'!R15 | AA10: =№1!Q15 | AB10: ='NiPA-62-F_UG_1__2026-03-24_11-4'!Q15 | AC10: ='NiPA-62-F_UG_2__2026-03-24_11-5'!Q15 | AD10: ='NiPA-62-F_UG_3__2026-03-24_13-0'!Q15 | AE10: ='NiPA-62-F_UG_4__2026-03-24_13-1'!Q15 | AF10: ='NiPA-62-F_UG_5__2026-03-24_13-2'!Q15 | AG10: ='NiPA-62-F_UG_6__2026-03-24_13-2'!Q15 | AH10: ='NiPA-62-F_UG_7__2026-03-24_13-3'!Q15 | AI10: =№1!S15 | AJ10: ='NiPA-62-F_UG_1__2026-03-24_11-4'!S15 | AK10: ='NiPA-62-F_UG_2__2026-03-24_11-5'!S15 | AL10: ='NiPA-62-F_UG_3__2026-03-24_13-0'!S15 | AM10: ='NiPA-62-F_UG_4__2026-03-24_13-1'!S15 | AN10: ='NiPA-62-F_UG_5__2026-03-24_13-2'!S15 | AO10: ='NiPA-62-F_UG_6__2026-03-24_13-2'!S15 | AP10: ='NiPA-62-F_UG_7__2026-03-24_13-3'!S15 | AQ10: =№1!T15 | AR10: ='NiPA-62-F_UG_1__2026-03-24_11-4'!T15 | AS10: ='NiPA-62-F_UG_2__2026-03-24_11-5'!T15 | AT10: ='NiPA-62-F_UG_3__2026-03-24_13-0'!T15 | AU10: ='NiPA-62-F_UG_4__2026-03-24_13-1'!T15 | AV10: ='NiPA-62-F_UG_5__2026-03-24_13-2'!T15 | AW10: ='NiPA-62-F_UG_6__2026-03-24_13-2'!T15 | AX10: ='NiPA-62-F_UG_7__2026-03-24_13-3'!T15
A11: ='NiPA-62-F_UG_7__2026-03-24_13-3'!B16 | B11: =A11/1000000000 | C11: =№1!U16 | D11: ='NiPA-62-F_UG_1__2026-03-24_11-4'!U16 | E11: ='NiPA-62-F_UG_2__2026-03-24_11-5'!U16 | F11: ='NiPA-62-F_UG_3__2026-03-24_13-0'!U16 | G11: ='NiPA-62-F_UG_4__2026-03-24_13-1'!U16 | H11: ='NiPA-62-F_UG_5__2026-03-24_13-2'!U16 | I11: ='NiPA-62-F_UG_6__2026-03-24_13-2'!U16 | J11: ='NiPA-62-F_UG_7__2026-03-24_13-3'!U16 | K11: =№1!P16 | L11: ='NiPA-62-F_UG_1__2026-03-24_11-4'!P16 | M11: ='NiPA-62-F_UG_2__2026-03-24_11-5'!P16 | N11: ='NiPA-62-F_UG_3__2026-03-24_13-0'!P16 | O11: ='NiPA-62-F_UG_4__2026-03-24_13-1'!P16 | P11: ='NiPA-62-F_UG_5__2026-03-24_13-2'!P16 | Q11: ='NiPA-62-F_UG_6__2026-03-24_13-2'!P16 | R11: ='NiPA-62-F_UG_7__2026-03-24_13-3'!P16 | S11: =№1!R16 | T11: ='NiPA-62-F_UG_1__2026-03-24_11-4'!R16 | U11: ='NiPA-62-F_UG_2__2026-03-24_11-5'!R16 | V11: ='NiPA-62-F_UG_3__2026-03-24_13-0'!R16 | W11: ='NiPA-62-F_UG_4__2026-03-24_13-1'!R16 | X11: ='NiPA-62-F_UG_5__2026-03-24_13-2'!R16 | Y11: ='NiPA-62-F_UG_6__2026-03-24_13-2'!R16 | Z11: ='NiPA-62-F_UG_7__2026-03-24_13-3'!R16 | AA11: =№1!Q16 | AB11: ='NiPA-62-F_UG_1__2026-03-24_11-4'!Q16 | AC11: ='NiPA-62-F_UG_2__2026-03-24_11-5'!Q16 | AD11: ='NiPA-62-F_UG_3__2026-03-24_13-0'!Q16 | AE11: ='NiPA-62-F_UG_4__2026-03-24_13-1'!Q16 | AF11: ='NiPA-62-F_UG_5__2026-03-24_13-2'!Q16 | AG11: ='NiPA-62-F_UG_6__2026-03-24_13-2'!Q16 | AH11: ='NiPA-62-F_UG_7__2026-03-24_13-3'!Q16 | AI11: =№1!S16 | AJ11: ='NiPA-62-F_UG_1__2026-03-24_11-4'!S16 | AK11: ='NiPA-62-F_UG_2__2026-03-24_11-5'!S16 | AL11: ='NiPA-62-F_UG_3__2026-03-24_13-0'!S16 | AM11: ='NiPA-62-F_UG_4__2026-03-24_13-1'!S16 | AN11: ='NiPA-62-F_UG_5__2026-03-24_13-2'!S16 | AO11: ='NiPA-62-F_UG_6__2026-03-24_13-2'!S16 | AP11: ='NiPA-62-F_UG_7__2026-03-24_13-3'!S16 | AQ11: =№1!T16 | AR11: ='NiPA-62-F_UG_1__2026-03-24_11-4'!T16 | AS11: ='NiPA-62-F_UG_2__2026-03-24_11-5'!T16 | AT11: ='NiPA-62-F_UG_3__2026-03-24_13-0'!T16 | AU11: ='NiPA-62-F_UG_4__2026-03-24_13-1'!T16 | AV11: ='NiPA-62-F_UG_5__2026-03-24_13-2'!T16 | AW11: ='NiPA-62-F_UG_6__2026-03-24_13-2'!T16 | AX11: ='NiPA-62-F_UG_7__2026-03-24_13-3'!T16
A12: ='NiPA-62-F_UG_7__2026-03-24_13-3'!B17 | B12: =A12/1000000000 | C12: =№1!U17 | D12: ='NiPA-62-F_UG_1__2026-03-24_11-4'!U17 | E12: ='NiPA-62-F_UG_2__2026-03-24_11-5'!U17 | F12: ='NiPA-62-F_UG_3__2026-03-24_13-0'!U17 | G12: ='NiPA-62-F_UG_4__2026-03-24_13-1'!U17 | H12: ='NiPA-62-F_UG_5__2026-03-24_13-2'!U17 | I12: ='NiPA-62-F_UG_6__2026-03-24_13-2'!U17 | J12: ='NiPA-62-F_UG_7__2026-03-24_13-3'!U17 | K12: =№1!P17 | L12: ='NiPA-62-F_UG_1__2026-03-24_11-4'!P17 | M12: ='NiPA-62-F_UG_2__2026-03-24_11-5'!P17 | N12: ='NiPA-62-F_UG_3__2026-03-24_13-0'!P17 | O12: ='NiPA-62-F_UG_4__2026-03-24_13-1'!P17 | P12: ='NiPA-62-F_UG_5__2026-03-24_13-2'!P17 | Q12: ='NiPA-62-F_UG_6__2026-03-24_13-2'!P17 | R12: ='NiPA-62-F_UG_7__2026-03-24_13-3'!P17 | S12: =№1!R17 | T12: ='NiPA-62-F_UG_1__2026-03-24_11-4'!R17 | U12: ='NiPA-62-F_UG_2__2026-03-24_11-5'!R17 | V12: ='NiPA-62-F_UG_3__2026-03-24_13-0'!R17 | W12: ='NiPA-62-F_UG_4__2026-03-24_13-1'!R17 | X12: ='NiPA-62-F_UG_5__2026-03-24_13-2'!R17 | Y12: ='NiPA-62-F_UG_6__2026-03-24_13-2'!R17 | Z12: ='NiPA-62-F_UG_7__2026-03-24_13-3'!R17 | AA12: =№1!Q17 | AB12: ='NiPA-62-F_UG_1__2026-03-24_11-4'!Q17 | AC12: ='NiPA-62-F_UG_2__2026-03-24_11-5'!Q17 | AD12: ='NiPA-62-F_UG_3__2026-03-24_13-0'!Q17 | AE12: ='NiPA-62-F_UG_4__2026-03-24_13-1'!Q17 | AF12: ='NiPA-62-F_UG_5__2026-03-24_13-2'!Q17 | AG12: ='NiPA-62-F_UG_6__2026-03-24_13-2'!Q17 | AH12: ='NiPA-62-F_UG_7__2026-03-24_13-3'!Q17 | AI12: =№1!S17 | AJ12: ='NiPA-62-F_UG_1__2026-03-24_11-4'!S17 | AK12: ='NiPA-62-F_UG_2__2026-03-24_11-5'!S17 | AL12: ='NiPA-62-F_UG_3__2026-03-24_13-0'!S17 | AM12: ='NiPA-62-F_UG_4__2026-03-24_13-1'!S17 | AN12: ='NiPA-62-F_UG_5__2026-03-24_13-2'!S17 | AO12: ='NiPA-62-F_UG_6__2026-03-24_13-2'!S17 | AP12: ='NiPA-62-F_UG_7__2026-03-24_13-3'!S17 | AQ12: =№1!T17 | AR12: ='NiPA-62-F_UG_1__2026-03-24_11-4'!T17 | AS12: ='NiPA-62-F_UG_2__2026-03-24_11-5'!T17 | AT12: ='NiPA-62-F_UG_3__2026-03-24_13-0'!T17 | AU12: ='NiPA-62-F_UG_4__2026-03-24_13-1'!T17 | AV12: ='NiPA-62-F_UG_5__2026-03-24_13-2'!T17 | AW12: ='NiPA-62-F_UG_6__2026-03-24_13-2'!T17 | AX12: ='NiPA-62-F_UG_7__2026-03-24_13-3'!T17
A13: ='NiPA-62-F_UG_7__2026-03-24_13-3'!B18 | B13: =A13/1000000000 | C13: =№1!U18 | D13: ='NiPA-62-F_UG_1__2026-03-24_11-4'!U18 | E13: ='NiPA-62-F_UG_2__2026-03-24_11-5'!U18 | F13: ='NiPA-62-F_UG_3__2026-03-24_13-0'!U18 | G13: ='NiPA-62-F_UG_4__2026-03-24_13-1'!U18 | H13: ='NiPA-62-F_UG_5__2026-03-24_13-2'!U18 | I13: ='NiPA-62-F_UG_6__2026-03-24_13-2'!U18 | J13: ='NiPA-62-F_UG_7__2026-03-24_13-3'!U18 | K13: =№1!P18 | L13: ='NiPA-62-F_UG_1__2026-03-24_11-4'!P18 | M13: ='NiPA-62-F_UG_2__2026-03-24_11-5'!P18 | N13: ='NiPA-62-F_UG_3__2026-03-24_13-0'!P18 | O13: ='NiPA-62-F_UG_4__2026-03-24_13-1'!P18 | P13: ='NiPA-62-F_UG_5__2026-03-24_13-2'!P18 | Q13: ='NiPA-62-F_UG_6__2026-03-24_13-2'!P18 | R13: ='NiPA-62-F_UG_7__2026-03-24_13-3'!P18 | S13: =№1!R18 | T13: ='NiPA-62-F_UG_1__2026-03-24_11-4'!R18 | U13: ='NiPA-62-F_UG_2__2026-03-24_11-5'!R18 | V13: ='NiPA-62-F_UG_3__2026-03-24_13-0'!R18 | W13: ='NiPA-62-F_UG_4__2026-03-24_13-1'!R18 | X13: ='NiPA-62-F_UG_5__2026-03-24_13-2'!R18 | Y13: ='NiPA-62-F_UG_6__2026-03-24_13-2'!R18 | Z13: ='NiPA-62-F_UG_7__2026-03-24_13-3'!R18 | AA13: =№1!Q18 | AB13: ='NiPA-62-F_UG_1__2026-03-24_11-4'!Q18 | AC13: ='NiPA-62-F_UG_2__2026-03-24_11-5'!Q18 | AD13: ='NiPA-62-F_UG_3__2026-03-24_13-0'!Q18 | AE13: ='NiPA-62-F_UG_4__2026-03-24_13-1'!Q18 | AF13: ='NiPA-62-F_UG_5__2026-03-24_13-2'!Q18 | AG13: ='NiPA-62-F_UG_6__2026-03-24_13-2'!Q18 | AH13: ='NiPA-62-F_UG_7__2026-03-24_13-3'!Q18 | AI13: =№1!S18 | AJ13: ='NiPA-62-F_UG_1__2026-03-24_11-4'!S18 | AK13: ='NiPA-62-F_UG_2__2026-03-24_11-5'!S18 | AL13: ='NiPA-62-F_UG_3__2026-03-24_13-0'!S18 | AM13: ='NiPA-62-F_UG_4__2026-03-24_13-1'!S18 | AN13: ='NiPA-62-F_UG_5__2026-03-24_13-2'!S18 | AO13: ='NiPA-62-F_UG_6__2026-03-24_13-2'!S18 | AP13: ='NiPA-62-F_UG_7__2026-03-24_13-3'!S18 | AQ13: =№1!T18 | AR13: ='NiPA-62-F_UG_1__2026-03-24_11-4'!T18 | AS13: ='NiPA-62-F_UG_2__2026-03-24_11-5'!T18 | AT13: ='NiPA-62-F_UG_3__2026-03-24_13-0'!T18 | AU13: ='NiPA-62-F_UG_4__2026-03-24_13-1'!T18 | AV13: ='NiPA-62-F_UG_5__2026-03-24_13-2'!T18 | AW13: ='NiPA-62-F_UG_6__2026-03-24_13-2'!T18 | AX13: ='NiPA-62-F_UG_7__2026-03-24_13-3'!T18
A14: ='NiPA-62-F_UG_7__2026-03-24_13-3'!B19 | B14: =A14/1000000000 | C14: =№1!U19 | D14: ='NiPA-62-F_UG_1__2026-03-24_11-4'!U19 | E14: ='NiPA-62-F_UG_2__2026-03-24_11-5'!U19 | F14: ='NiPA-62-F_UG_3__2026-03-24_13-0'!U19 | G14: ='NiPA-62-F_UG_4__2026-03-24_13-1'!U19 | H14: ='NiPA-62-F_UG_5__2026-03-24_13-2'!U19 | I14: ='NiPA-62-F_UG_6__2026-03-24_13-2'!U19 | J14: ='NiPA-62-F_UG_7__2026-03-24_13-3'!U19 | K14: =№1!P19 | L14: ='NiPA-62-F_UG_1__2026-03-24_11-4'!P19 | M14: ='NiPA-62-F_UG_2__2026-03-24_11-5'!P19 | N14: ='NiPA-62-F_UG_3__2026-03-24_13-0'!P19 | O14: ='NiPA-62-F_UG_4__2026-03-24_13-1'!P19 | P14: ='NiPA-62-F_UG_5__2026-03-24_13-2'!P19 | Q14: ='NiPA-62-F_UG_6__2026-03-24_13-2'!P19 | R14: ='NiPA-62-F_UG_7__2026-03-24_13-3'!P19 | S14: =№1!R19 | T14: ='NiPA-62-F_UG_1__2026-03-24_11-4'!R19 | U14: ='NiPA-62-F_UG_2__2026-03-24_11-5'!R19 | V14: ='NiPA-62-F_UG_3__2026-03-24_13-0'!R19 | W14: ='NiPA-62-F_UG_4__2026-03-24_13-1'!R19 | X14: ='NiPA-62-F_UG_5__2026-03-24_13-2'!R19 | Y14: ='NiPA-62-F_UG_6__2026-03-24_13-2'!R19 | Z14: ='NiPA-62-F_UG_7__2026-03-24_13-3'!R19 | AA14: =№1!Q19 | AB14: ='NiPA-62-F_UG_1__2026-03-24_11-4'!Q19 | AC14: ='NiPA-62-F_UG_2__2026-03-24_11-5'!Q19 | AD14: ='NiPA-62-F_UG_3__2026-03-24_13-0'!Q19 | AE14: ='NiPA-62-F_UG_4__2026-03-24_13-1'!Q19 | AF14: ='NiPA-62-F_UG_5__2026-03-24_13-2'!Q19 | AG14: ='NiPA-62-F_UG_6__2026-03-24_13-2'!Q19 | AH14: ='NiPA-62-F_UG_7__2026-03-24_13-3'!Q19 | AI14: =№1!S19 | AJ14: ='NiPA-62-F_UG_1__2026-03-24_11-4'!S19 | AK14: ='NiPA-62-F_UG_2__2026-03-24_11-5'!S19 | AL14: ='NiPA-62-F_UG_3__2026-03-24_13-0'!S19 | AM14: ='NiPA-62-F_UG_4__2026-03-24_13-1'!S19 | AN14: ='NiPA-62-F_UG_5__2026-03-24_13-2'!S19 | AO14: ='NiPA-62-F_UG_6__2026-03-24_13-2'!S19 | AP14: ='NiPA-62-F_UG_7__2026-03-24_13-3'!S19 | AQ14: =№1!T19 | AR14: ='NiPA-62-F_UG_1__2026-03-24_11-4'!T19 | AS14: ='NiPA-62-F_UG_2__2026-03-24_11-5'!T19 | AT14: ='NiPA-62-F_UG_3__2026-03-24_13-0'!T19 | AU14: ='NiPA-62-F_UG_4__2026-03-24_13-1'!T19 | AV14: ='NiPA-62-F_UG_5__2026-03-24_13-2'!T19 | AW14: ='NiPA-62-F_UG_6__2026-03-24_13-2'!T19 | AX14: ='NiPA-62-F_UG_7__2026-03-24_13-3'!T19
A15: ='NiPA-62-F_UG_7__2026-03-24_13-3'!B20 | B15: =A15/1000000000 | C15: =№1!U20 | D15: ='NiPA-62-F_UG_1__2026-03-24_11-4'!U20 | E15: ='NiPA-62-F_UG_2__2026-03-24_11-5'!U20 | F15: ='NiPA-62-F_UG_3__2026-03-24_13-0'!U20 | G15: ='NiPA-62-F_UG_4__2026-03-24_13-1'!U20 | H15: ='NiPA-62-F_UG_5__2026-03-24_13-2'!U20 | I15: ='NiPA-62-F_UG_6__2026-03-24_13-2'!U20 | J15: ='NiPA-62-F_UG_7__2026-03-24_13-3'!U20 | K15: =№1!P20 | L15: ='NiPA-62-F_UG_1__2026-03-24_11-4'!P20 | M15: ='NiPA-62-F_UG_2__2026-03-24_11-5'!P20 | N15: ='NiPA-62-F_UG_3__2026-03-24_13-0'!P20 | O15: ='NiPA-62-F_UG_4__2026-03-24_13-1'!P20 | P15: ='NiPA-62-F_UG_5__2026-03-24_13-2'!P20 | Q15: ='NiPA-62-F_UG_6__2026-03-24_13-2'!P20 | R15: ='NiPA-62-F_UG_7__2026-03-24_13-3'!P20 | S15: =№1!R20 | T15: ='NiPA-62-F_UG_1__2026-03-24_11-4'!R20 | U15: ='NiPA-62-F_UG_2__2026-03-24_11-5'!R20 | V15: ='NiPA-62-F_UG_3__2026-03-24_13-0'!R20 | W15: ='NiPA-62-F_UG_4__2026-03-24_13-1'!R20 | X15: ='NiPA-62-F_UG_5__2026-03-24_13-2'!R20 | Y15: ='NiPA-62-F_UG_6__2026-03-24_13-2'!R20 | Z15: ='NiPA-62-F_UG_7__2026-03-24_13-3'!R20 | AA15: =№1!Q20 | AB15: ='NiPA-62-F_UG_1__2026-03-24_11-4'!Q20 | AC15: ='NiPA-62-F_UG_2__2026-03-24_11-5'!Q20 | AD15: ='NiPA-62-F_UG_3__2026-03-24_13-0'!Q20 | AE15: ='NiPA-62-F_UG_4__2026-03-24_13-1'!Q20 | AF15: ='NiPA-62-F_UG_5__2026-03-24_13-2'!Q20 | AG15: ='NiPA-62-F_UG_6__2026-03-24_13-2'!Q20 | AH15: ='NiPA-62-F_UG_7__2026-03-24_13-3'!Q20 | AI15: =№1!S20 | AJ15: ='NiPA-62-F_UG_1__2026-03-24_11-4'!S20 | AK15: ='NiPA-62-F_UG_2__2026-03-24_11-5'!S20 | AL15: ='NiPA-62-F_UG_3__2026-03-24_13-0'!S20 | AM15: ='NiPA-62-F_UG_4__2026-03-24_13-1'!S20 | AN15: ='NiPA-62-F_UG_5__2026-03-24_13-2'!S20 | AO15: ='NiPA-62-F_UG_6__2026-03-24_13-2'!S20 | AP15: ='NiPA-62-F_UG_7__2026-03-24_13-3'!S20 | AQ15: =№1!T20 | AR15: ='NiPA-62-F_UG_1__2026-03-24_11-4'!T20 | AS15: ='NiPA-62-F_UG_2__2026-03-24_11-5'!T20 | AT15: ='NiPA-62-F_UG_3__2026-03-24_13-0'!T20 | AU15: ='NiPA-62-F_UG_4__2026-03-24_13-1'!T20 | AV15: ='NiPA-62-F_UG_5__2026-03-24_13-2'!T20 | AW15: ='NiPA-62-F_UG_6__2026-03-24_13-2'!T20 | AX15: ='NiPA-62-F_UG_7__2026-03-24_13-3'!T20
A16: ='NiPA-62-F_UG_7__2026-03-24_13-3'!B21 | B16: =A16/1000000000 | C16: =№1!U21 | D16: ='NiPA-62-F_UG_1__2026-03-24_11-4'!U21 | E16: ='NiPA-62-F_UG_2__2026-03-24_11-5'!U21 | F16: ='NiPA-62-F_UG_3__2026-03-24_13-0'!U21 | G16: ='NiPA-62-F_UG_4__2026-03-24_13-1'!U21 | H16: ='NiPA-62-F_UG_5__2026-03-24_13-2'!U21 | I16: ='NiPA-62-F_UG_6__2026-03-24_13-2'!U21 | J16: ='NiPA-62-F_UG_7__2026-03-24_13-3'!U21 | K16: =№1!P21 | L16: ='NiPA-62-F_UG_1__2026-03-24_11-4'!P21 | M16: ='NiPA-62-F_UG_2__2026-03-24_11-5'!P21 | N16: ='NiPA-62-F_UG_3__2026-03-24_13-0'!P21 | O16: ='NiPA-62-F_UG_4__2026-03-24_13-1'!P21 | P16: ='NiPA-62-F_UG_5__2026-03-24_13-2'!P21 | Q16: ='NiPA-62-F_UG_6__2026-03-24_13-2'!P21 | R16: ='NiPA-62-F_UG_7__2026-03-24_13-3'!P21 | S16: =№1!R21 | T16: ='NiPA-62-F_UG_1__2026-03-24_11-4'!R21 | U16: ='NiPA-62-F_UG_2__2026-03-24_11-5'!R21 | V16: ='NiPA-62-F_UG_3__2026-03-24_13-0'!R21 | W16: ='NiPA-62-F_UG_4__2026-03-24_13-1'!R21 | X16: ='NiPA-62-F_UG_5__2026-03-24_13-2'!R21 | Y16: ='NiPA-62-F_UG_6__2026-03-24_13-2'!R21 | Z16: ='NiPA-62-F_UG_7__2026-03-24_13-3'!R21 | AA16: =№1!Q21 | AB16: ='NiPA-62-F_UG_1__2026-03-24_11-4'!Q21 | AC16: ='NiPA-62-F_UG_2__2026-03-24_11-5'!Q21 | AD16: ='NiPA-62-F_UG_3__2026-03-24_13-0'!Q21 | AE16: ='NiPA-62-F_UG_4__2026-03-24_13-1'!Q21 | AF16: ='NiPA-62-F_UG_5__2026-03-24_13-2'!Q21 | AG16: ='NiPA-62-F_UG_6__2026-03-24_13-2'!Q21 | AH16: ='NiPA-62-F_UG_7__2026-03-24_13-3'!Q21 | AI16: =№1!S21 | AJ16: ='NiPA-62-F_UG_1__2026-03-24_11-4'!S21 | AK16: ='NiPA-62-F_UG_2__2026-03-24_11-5'!S21 | AL16: ='NiPA-62-F_UG_3__2026-03-24_13-0'!S21 | AM16: ='NiPA-62-F_UG_4__2026-03-24_13-1'!S21 | AN16: ='NiPA-62-F_UG_5__2026-03-24_13-2'!S21 | AO16: ='NiPA-62-F_UG_6__2026-03-24_13-2'!S21 | AP16: ='NiPA-62-F_UG_7__2026-03-24_13-3'!S21 | AQ16: =№1!T21 | AR16: ='NiPA-62-F_UG_1__2026-03-24_11-4'!T21 | AS16: ='NiPA-62-F_UG_2__2026-03-24_11-5'!T21 | AT16: ='NiPA-62-F_UG_3__2026-03-24_13-0'!T21 | AU16: ='NiPA-62-F_UG_4__2026-03-24_13-1'!T21 | AV16: ='NiPA-62-F_UG_5__2026-03-24_13-2'!T21 | AW16: ='NiPA-62-F_UG_6__2026-03-24_13-2'!T21 | AX16: ='NiPA-62-F_UG_7__2026-03-24_13-3'!T21
A17: ='NiPA-62-F_UG_7__2026-03-24_13-3'!B22 | B17: =A17/1000000000 | C17: =№1!U22 | D17: ='NiPA-62-F_UG_1__2026-03-24_11-4'!U22 | E17: ='NiPA-62-F_UG_2__2026-03-24_11-5'!U22 | F17: ='NiPA-62-F_UG_3__2026-03-24_13-0'!U22 | G17: ='NiPA-62-F_UG_4__2026-03-24_13-1'!U22 | H17: ='NiPA-62-F_UG_5__2026-03-24_13-2'!U22 | I17: ='NiPA-62-F_UG_6__2026-03-24_13-2'!U22 | J17: ='NiPA-62-F_UG_7__2026-03-24_13-3'!U22 | K17: =№1!P22 | L17: ='NiPA-62-F_UG_1__2026-03-24_11-4'!P22 | M17: ='NiPA-62-F_UG_2__2026-03-24_11-5'!P22 | N17: ='NiPA-62-F_UG_3__2026-03-24_13-0'!P22 | O17: ='NiPA-62-F_UG_4__2026-03-24_13-1'!P22 | P17: ='NiPA-62-F_UG_5__2026-03-24_13-2'!P22 | Q17: ='NiPA-62-F_UG_6__2026-03-24_13-2'!P22 | R17: ='NiPA-62-F_UG_7__2026-03-24_13-3'!P22 | S17: =№1!R22 | T17: ='NiPA-62-F_UG_1__2026-03-24_11-4'!R22 | U17: ='NiPA-62-F_UG_2__2026-03-24_11-5'!R22 | V17: ='NiPA-62-F_UG_3__2026-03-24_13-0'!R22 | W17: ='NiPA-62-F_UG_4__2026-03-24_13-1'!R22 | X17: ='NiPA-62-F_UG_5__2026-03-24_13-2'!R22 | Y17: ='NiPA-62-F_UG_6__2026-03-24_13-2'!R22 | Z17: ='NiPA-62-F_UG_7__2026-03-24_13-3'!R22 | AA17: =№1!Q22 | AB17: ='NiPA-62-F_UG_1__2026-03-24_11-4'!Q22 | AC17: ='NiPA-62-F_UG_2__2026-03-24_11-5'!Q22 | AD17: ='NiPA-62-F_UG_3__2026-03-24_13-0'!Q22 | AE17: ='NiPA-62-F_UG_4__2026-03-24_13-1'!Q22 | AF17: ='NiPA-62-F_UG_5__2026-03-24_13-2'!Q22 | AG17: ='NiPA-62-F_UG_6__2026-03-24_13-2'!Q22 | AH17: ='NiPA-62-F_UG_7__2026-03-24_13-3'!Q22 | AI17: =№1!S22 | AJ17: ='NiPA-62-F_UG_1__2026-03-24_11-4'!S22 | AK17: ='NiPA-62-F_UG_2__2026-03-24_11-5'!S22 | AL17: ='NiPA-62-F_UG_3__2026-03-24_13-0'!S22 | AM17: ='NiPA-62-F_UG_4__2026-03-24_13-1'!S22 | AN17: ='NiPA-62-F_UG_5__2026-03-24_13-2'!S22 | AO17: ='NiPA-62-F_UG_6__2026-03-24_13-2'!S22 | AP17: ='NiPA-62-F_UG_7__2026-03-24_13-3'!S22 | AQ17: =№1!T22 | AR17: ='NiPA-62-F_UG_1__2026-03-24_11-4'!T22 | AS17: ='NiPA-62-F_UG_2__2026-03-24_11-5'!T22 | AT17: ='NiPA-62-F_UG_3__2026-03-24_13-0'!T22 | AU17: ='NiPA-62-F_UG_4__2026-03-24_13-1'!T22 | AV17: ='NiPA-62-F_UG_5__2026-03-24_13-2'!T22 | AW17: ='NiPA-62-F_UG_6__2026-03-24_13-2'!T22 | AX17: ='NiPA-62-F_UG_7__2026-03-24_13-3'!T22
... A41: ='NiPA-62-F_UG_7__2026-03-24_13-3'!B46 | B41: =A41/1000000000 | C41: =№1!U46 | D41: ='NiPA-62-F_UG_1__2026-03-24_11-4'!U46 | E41: ='NiPA-62-F_UG_2__2026-03-24_11-5'!U46 | F41: ='NiPA-62-F_UG_3__2026-03-24_13-0'!U46 | G41: ='NiPA-62-F_UG_4__2026-03-24_13-1'!U46 | H41: ='NiPA-62-F_UG_5__2026-03-24_13-2'!U46 | I41: ='NiPA-62-F_UG_6__2026-03-24_13-2'!U46 | J41: ='NiPA-62-F_UG_7__2026-03-24_13-3'!U46 | K41: =№1!P46 | L41: ='NiPA-62-F_UG_1__2026-03-24_11-4'!P46 | M41: ='NiPA-62-F_UG_2__2026-03-24_11-5'!P46 | N41: ='NiPA-62-F_UG_3__2026-03-24_13-0'!P46 | O41: ='NiPA-62-F_UG_4__2026-03-24_13-1'!P46 | P41: ='NiPA-62-F_UG_5__2026-03-24_13-2'!P46 | Q41: ='NiPA-62-F_UG_6__2026-03-24_13-2'!P46 | R41: ='NiPA-62-F_UG_7__2026-03-24_13-3'!P46 | S41: =№1!R46 | T41: ='NiPA-62-F_UG_1__2026-03-24_11-4'!R46 | U41: ='NiPA-62-F_UG_2__2026-03-24_11-5'!R46 | V41: ='NiPA-62-F_UG_3__2026-03-24_13-0'!R46 | W41: ='NiPA-62-F_UG_4__2026-03-24_13-1'!R46 | X41: ='NiPA-62-F_UG_5__2026-03-24_13-2'!R46 | Y41: ='NiPA-62-F_UG_6__2026-03-24_13-2'!R46 | Z41: ='NiPA-62-F_UG_7__2026-03-24_13-3'!R46 | AA41: =№1!Q46 | AB41: ='NiPA-62-F_UG_1__2026-03-24_11-4'!Q46 | AC41: ='NiPA-62-F_UG_2__2026-03-24_11-5'!Q46 | AD41: ='NiPA-62-F_UG_3__2026-03-24_13-0'!Q46 | AE41: ='NiPA-62-F_UG_4__2026-03-24_13-1'!Q46 | AF41: ='NiPA-62-F_UG_5__2026-03-24_13-2'!Q46 | AG41: ='NiPA-62-F_UG_6__2026-03-24_13-2'!Q46 | AH41: ='NiPA-62-F_UG_7__2026-03-24_13-3'!Q46 | AI41: =№1!S46 | AJ41: ='NiPA-62-F_UG_1__2026-03-24_11-4'!S46 | AK41: ='NiPA-62-F_UG_2__2026-03-24_11-5'!S46 | AL41: ='NiPA-62-F_UG_3__2026-03-24_13-0'!S46 | AM41: ='NiPA-62-F_UG_4__2026-03-24_13-1'!S46 | AN41: ='NiPA-62-F_UG_5__2026-03-24_13-2'!S46 | AO41: ='NiPA-62-F_UG_6__2026-03-24_13-2'!S46 | AP41: ='NiPA-62-F_UG_7__2026-03-24_13-3'!S46 | AQ41: =№1!T46 | AR41: ='NiPA-62-F_UG_1__2026-03-24_11-4'!T46 | AS41: ='NiPA-62-F_UG_2__2026-03-24_11-5'!T46 | AT41: ='NiPA-62-F_UG_3__2026-03-24_13-0'!T46 | AU41: ='NiPA-62-F_UG_4__2026-03-24_13-1'!T46 | AV41: ='NiPA-62-F_UG_5__2026-03-24_13-2'!T46 | AW41: ='NiPA-62-F_UG_6__2026-03-24_13-2'!T46 | AX41: ='NiPA-62-F_UG_7__2026-03-24_13-3'!T46
A42: =#REF! | B42: =A42/1000000000 | C42: =№1!U47 | D42: =#REF! | E42: =#REF! | F42: =#REF! | G42: =#REF! | H42: =#REF! | I42: =#REF! | J42: =#REF! | K42: =№1!P47 | L42: =#REF! | M42: =#REF! | N42: =#REF! | O42: =#REF! | P42: =#REF! | Q42: =#REF! | R42: =#REF! | S42: =№1!R47 | T42: =#REF! | U42: =#REF! | V42: =#REF! | W42: =#REF! | X42: =#REF! | Y42: =#REF! | Z42: =#REF! | AA42: =№1!Q47 | AB42: =#REF! | AC42: =#REF! | AD42: =#REF! | AE42: =#REF! | AF42: =#REF! | AG42: =#REF! | AH42: =#REF! | AI42: =№1!S47 | AJ42: =#REF! | AK42: =#REF! | AL42: =#REF! | AM42: =#REF! | AN42: =#REF! | AO42: =#REF! | AP42: =#REF! | AQ42: =№1!T47 | AR42: =#REF! | AS42: =#REF! | AT42: =#REF! | AU42: =#REF! | AV42: =#REF! | AW42: =#REF! | AX42: =#REF!
A43: =#REF! | B43: =A43/1000000000 | C43: =№1!U48 | D43: =#REF! | E43: =#REF! | F43: =#REF! | G43: =#REF! | H43: =#REF! | I43: =#REF! | J43: =#REF! | K43: =№1!P48 | L43: =#REF! | M43: =#REF! | N43: =#REF! | O43: =#REF! | P43: =#REF! | Q43: =#REF! | R43: =#REF! | S43: =№1!R48 | T43: =#REF! | U43: =#REF! | V43: =#REF! | W43: =#REF! | X43: =#REF! | Y43: =#REF! | Z43: =#REF! | AA43: =№1!Q48 | AB43: =#REF! | AC43: =#REF! | AD43: =#REF! | AE43: =#REF! | AF43: =#REF! | AG43: =#REF! | AH43: =#REF! | AI43: =№1!S48 | AJ43: =#REF! | AK43: =#REF! | AL43: =#REF! | AM43: =#REF! | AN43: =#REF! | AO43: =#REF! | AP43: =#REF! | AQ43: =№1!T48 | AR43: =#REF! | AS43: =#REF! | AT43: =#REF! | AU43: =#REF! | AV43: =#REF! | AW43: =#REF! | AX43: =#REF!
A44: =#REF! | B44: =A44/1000000000 | C44: =№1!U49 | D44: =#REF! | E44: =#REF! | F44: =#REF! | G44: =#REF! | H44: =#REF! | I44: =#REF! | J44: =#REF! | K44: =№1!P49 | L44: =#REF! | M44: =#REF! | N44: =#REF! | O44: =#REF! | P44: =#REF! | Q44: =#REF! | R44: =#REF! | S44: =№1!R49 | T44: =#REF! | U44: =#REF! | V44: =#REF! | W44: =#REF! | X44: =#REF! | Y44: =#REF! | Z44: =#REF! | AA44: =№1!Q49 | AB44: =#REF! | AC44: =#REF! | AD44: =#REF! | AE44: =#REF! | AF44: =#REF! | AG44: =#REF! | AH44: =#REF! | AI44: =№1!S49 | AJ44: =#REF! | AK44: =#REF! | AL44: =#REF! | AM44: =#REF! | AN44: =#REF! | AO44: =#REF! | AP44: =#REF! | AQ44: =№1!T49 | AR44: =#REF! | AS44: =#REF! | AT44: =#REF! | AU44: =#REF! | AV44: =#REF! | AW44: =#REF! | AX44: =#REF!
A45: =#REF! | B45: =A45/1000000000 | C45: =№1!U50 | D45: =#REF! | E45: =#REF! | F45: =#REF! | G45: =#REF! | H45: =#REF! | I45: =#REF! | J45: =#REF! | K45: =№1!P50 | L45: =#REF! | M45: =#REF! | N45: =#REF! | O45: =#REF! | P45: =#REF! | Q45: =#REF! | R45: =#REF! | S45: =№1!R50 | T45: =#REF! | U45: =#REF! | V45: =#REF! | W45: =#REF! | X45: =#REF! | Y45: =#REF! | Z45: =#REF! | AA45: =№1!Q50 | AB45: =#REF! | AC45: =#REF! | AD45: =#REF! | AE45: =#REF! | AF45: =#REF! | AG45: =#REF! | AH45: =#REF! | AI45: =№1!S50 | AJ45: =#REF! | AK45: =#REF! | AL45: =#REF! | AM45: =#REF! | AN45: =#REF! | AO45: =#REF! | AP45: =#REF! | AQ45: =№1!T50 | AR45: =#REF! | AS45: =#REF! | AT45: =#REF! | AU45: =#REF! | AV45: =#REF! | AW45: =#REF! | AX45: =#REF!
A46: =#REF! | B46: =A46/1000000000 | C46: =№1!U51 | D46: =#REF! | E46: =#REF! | F46: =#REF! | G46: =#REF! | H46: =#REF! | I46: =#REF! | J46: =#REF! | K46: =№1!P51 | L46: =#REF! | M46: =#REF! | N46: =#REF! | O46: =#REF! | P46: =#REF! | Q46: =#REF! | R46: =#REF! | S46: =№1!R51 | T46: =#REF! | U46: =#REF! | V46: =#REF! | W46: =#REF! | X46: =#REF! | Y46: =#REF! | Z46: =#REF! | AA46: =№1!Q51 | AB46: =#REF! | AC46: =#REF! | AD46: =#REF! | AE46: =#REF! | AF46: =#REF! | AG46: =#REF! | AH46: =#REF! | AI46: =№1!S51 | AJ46: =#REF! | AK46: =#REF! | AL46: =#REF! | AM46: =#REF! | AN46: =#REF! | AO46: =#REF! | AP46: =#REF! | AQ46: =№1!T51 | AR46: =#REF! | AS46: =#REF! | AT46: =#REF! | AU46: =#REF! | AV46: =#REF! | AW46: =#REF! | AX46: =#REF!
A47: =#REF! | B47: =A47/1000000000 | C47: =№1!U52 | D47: =#REF! | E47: =#REF! | F47: =#REF! | G47: =#REF! | H47: =#REF! | I47: =#REF! | J47: =#REF! | K47: =№1!P52 | L47: =#REF! | M47: =#REF! | N47: =#REF! | O47: =#REF! | P47: =#REF! | Q47: =#REF! | R47: =#REF! | S47: =№1!R52 | T47: =#REF! | U47: =#REF! | V47: =#REF! | W47: =#REF! | X47: =#REF! | Y47: =#REF! | Z47: =#REF! | AA47: =№1!Q52 | AB47: =#REF! | AC47: =#REF! | AD47: =#REF! | AE47: =#REF! | AF47: =#REF! | AG47: =#REF! | AH47: =#REF! | AI47: =№1!S52 | AJ47: =#REF! | AK47: =#REF! | AL47: =#REF! | AM47: =#REF! | AN47: =#REF! | AO47: =#REF! | AP47: =#REF! | AQ47: =№1!T52 | AR47: =#REF! | AS47: =#REF! | AT47: =#REF! | AU47: =#REF! | AV47: =#REF! | AW47: =#REF! | AX47: =#REF!
A48: =#REF! | B48: =A48/1000000000 | C48: =№1!U53 | D48: =#REF! | E48: =#REF! | F48: =#REF! | G48: =#REF! | H48: =#REF! | I48: =#REF! | J48: =#REF! | K48: =№1!P53 | L48: =#REF! | M48: =#REF! | N48: =#REF! | O48: =#REF! | P48: =#REF! | Q48: =#REF! | R48: =#REF! | S48: =№1!R53 | T48: =#REF! | U48: =#REF! | V48: =#REF! | W48: =#REF! | X48: =#REF! | Y48: =#REF! | Z48: =#REF! | AA48: =№1!Q53 | AB48: =#REF! | AC48: =#REF! | AD48: =#REF! | AE48: =#REF! | AF48: =#REF! | AG48: =#REF! | AH48: =#REF! | AI48: =№1!S53 | AJ48: =#REF! | AK48: =#REF! | AL48: =#REF! | AM48: =#REF! | AN48: =#REF! | AO48: =#REF! | AP48: =#REF! | AQ48: =№1!T53 | AR48: =#REF! | AS48: =#REF! | AT48: =#REF! | AU48: =#REF! | AV48: =#REF! | AW48: =#REF! | AX48: =#REF!
A49: =#REF! | B49: =A49/1000000000 | C49: =№1!U54 | D49: =#REF! | E49: =#REF! | F49: =#REF! | G49: =#REF! | H49: =#REF! | I49: =#REF! | J49: =#REF! | K49: =№1!P54 | L49: =#REF! | M49: =#REF! | N49: =#REF! | O49: =#REF! | P49: =#REF! | Q49: =#REF! | R49: =#REF! | S49: =№1!R54 | T49: =#REF! | U49: =#REF! | V49: =#REF! | W49: =#REF! | X49: =#REF! | Y49: =#REF! | Z49: =#REF! | AA49: =№1!Q54 | AB49: =#REF! | AC49: =#REF! | AD49: =#REF! | AE49: =#REF! | AF49: =#REF! | AG49: =#REF! | AH49: =#REF! | AI49: =№1!S54 | AJ49: =#REF! | AK49: =#REF! | AL49: =#REF! | AM49: =#REF! | AN49: =#REF! | AO49: =#REF! | AP49: =#REF! | AQ49: =№1!T54 | AR49: =#REF! | AS49: =#REF! | AT49: =#REF! | AU49: =#REF! | AV49: =#REF! | AW49: =#REF! | AX49: =#REF!
A50: =#REF! | B50: =A50/1000000000 | C50: =№1!U55 | D50: =#REF! | E50: =#REF! | F50: =#REF! | G50: =#REF! | H50: =#REF! | I50: =#REF! | J50: =#REF! | K50: =№1!P55 | L50: =#REF! | M50: =#REF! | N50: =#REF! | O50: =#REF! | P50: =#REF! | Q50: =#REF! | R50: =#REF! | S50: =№1!R55 | T50: =#REF! | U50: =#REF! | V50: =#REF! | W50: =#REF! | X50: =#REF! | Y50: =#REF! | Z50: =#REF! | AA50: =№1!Q55 | AB50: =#REF! | AC50: =#REF! | AD50: =#REF! | AE50: =#REF! | AF50: =#REF! | AG50: =#REF! | AH50: =#REF! | AI50: =№1!S55 | AJ50: =#REF! | AK50: =#REF! | AL50: =#REF! | AM50: =#REF! | AN50: =#REF! | AO50: =#REF! | AP50: =#REF! | AQ50: =№1!T55 | AR50: =#REF! | AS50: =#REF! | AT50: =#REF! | AU50: =#REF! | AV50: =#REF! | AW50: =#REF! | AX50: =#REF!
A51: =#REF! | B51: =A51/1000000000 | C51: =№1!U56 | D51: =#REF! | E51: =#REF! | F51: =#REF! | G51: =#REF! | H51: =#REF! | I51: =#REF! | J51: =#REF! | K51: =№1!P56 | L51: =#REF! | M51: =#REF! | N51: =#REF! | O51: =#REF! | P51: =#REF! | Q51: =#REF! | R51: =#REF! | S51: =№1!R56 | T51: =#REF! | U51: =#REF! | V51: =#REF! | W51: =#REF! | X51: =#REF! | Y51: =#REF! | Z51: =#REF! | AA51: =№1!Q56 | AB51: =#REF! | AC51: =#REF! | AD51: =#REF! | AE51: =#REF! | AF51: =#REF! | AG51: =#REF! | AH51: =#REF! | AI51: =№1!S56 | AJ51: =#REF! | AK51: =#REF! | AL51: =#REF! | AM51: =#REF! | AN51: =#REF! | AO51: =#REF! | AP51: =#REF! | AQ51: =№1!T56 | AR51: =#REF! | AS51: =#REF! | AT51: =#REF! | AU51: =#REF! | AV51: =#REF! | AW51: =#REF! | AX51: =#REF!
A52: =#REF! | B52: =A52/1000000000 | C52: =№1!U57 | D52: =#REF! | E52: =#REF! | F52: =#REF! | G52: =#REF! | H52: =#REF! | I52: =#REF! | J52: =#REF! | K52: =№1!P57 | L52: =#REF! | M52: =#REF! | N52: =#REF! | O52: =#REF! | P52: =#REF! | Q52: =#REF! | R52: =#REF! | S52: =№1!R57 | T52: =#REF! | U52: =#REF! | V52: =#REF! | W52: =#REF! | X52: =#REF! | Y52: =#REF! | Z52: =#REF! | AA52: =№1!Q57 | AB52: =#REF! | AC52: =#REF! | AD52: =#REF! | AE52: =#REF! | AF52: =#REF! | AG52: =#REF! | AH52: =#REF! | AI52: =№1!S57 | AJ52: =#REF! | AK52: =#REF! | AL52: =#REF! | AM52: =#REF! | AN52: =#REF! | AO52: =#REF! | AP52: =#REF! | AQ52: =№1!T57 | AR52: =#REF! | AS52: =#REF! | AT52: =#REF! | AU52: =#REF! | AV52: =#REF! | AW52: =#REF! | AX52: =#REF!
A53: =#REF! | B53: =A53/1000000000 | C53: =№1!U58 | D53: =#REF! | E53: =#REF! | F53: =#REF! | G53: =#REF! | H53: =#REF! | I53: =#REF! | J53: =#REF! | K53: =№1!P58 | L53: =#REF! | M53: =#REF! | N53: =#REF! | O53: =#REF! | P53: =#REF! | Q53: =#REF! | R53: =#REF! | S53: =№1!R58 | T53: =#REF! | U53: =#REF! | V53: =#REF! | W53: =#REF! | X53: =#REF! | Y53: =#REF! | Z53: =#REF! | AA53: =№1!Q58 | AB53: =#REF! | AC53: =#REF! | AD53: =#REF! | AE53: =#REF! | AF53: =#REF! | AG53: =#REF! | AH53: =#REF! | AI53: =№1!S58 | AJ53: =#REF! | AK53: =#REF! | AL53: =#REF! | AM53: =#REF! | AN53: =#REF! | AO53: =#REF! | AP53: =#REF! | AQ53: =№1!T58 | AR53: =#REF! | AS53: =#REF! | AT53: =#REF! | AU53: =#REF! | AV53: =#REF! | AW53: =#REF! | AX53: =#REF!
... A91: =#REF! | B91: =A91/1000000000 | C91: =№1!U96 | D91: =#REF! | E91: =#REF! | F91: =#REF! | G91: =#REF! | H91: =#REF! | I91: =#REF! | J91: =#REF! | K91: =№1!P96 | L91: =#REF! | M91: =#REF! | N91: =#REF! | O91: =#REF! | P91: =#REF! | Q91: =#REF! | R91: =#REF! | S91: =№1!R96 | T91: =#REF! | U91: =#REF! | V91: =#REF! | W91: =#REF! | X91: =#REF! | Y91: =#REF! | Z91: =#REF! | AA91: =№1!Q96 | AB91: =#REF! | AC91: =#REF! | AD91: =#REF! | AE91: =#REF! | AF91: =#REF! | AG91: =#REF! | AH91: =#REF! | AI91: =№1!S96 | AJ91: =#REF! | AK91: =#REF! | AL91: =#REF! | AM91: =#REF! | AN91: =#REF! | AO91: =#REF! | AP91: =#REF! | AQ91: =№1!T96 | AR91: =#REF! | AS91: =#REF! | AT91: =#REF! | AU91: =#REF! | AV91: =#REF! | AW91: =#REF! | AX91: =#REF!

Sheet №1
A1: ћощность на ”Ѕћ, dBm | B1: 18
A2: Gate start, ms | B2: 20
A3: Gate lenght, ms | B3: 80
A4: T, ms | B4: 1000
A5: “очность подстройки, dBm | B5: 0.1
A6: Iпот(поко€), mA | B6: 650
A7: Uп, ¬ | B7: 28
A8: Uсм, ¬
A9: — калибровкой
A10: є | B10: f, MHz | C10: P, dBm | D10: IG, mA | E10: ID, A | F10: Gain, dB | G10: ѕƒ, % | H10: Pвых, W | J10: Потери | K10: Q | L10: Ig_пок, мА | M10: Iпок, А | N10: Uп, В | O10: Pвх, Вт | P10: =C10 | Q10: =D10 | R10: =E10 | S10: =F10 | T10: =G10 | U10: =H10
A11: 1 | B11: 500000000 | C11: 33.513217 | D11: 4.9e-05 | E11: 0.140955 | F11: 15.513217 | G11: 5.529739 | H11: 2.245545 | J11: 0 | K11: 1 | L11: 0 | M11: 0 | N11: =B7 | O11: =(10^(B1/10))/1000 | P11: =C11+J11 | Q11: =D11-L11 | R11: =(E11-M11)*K11 | S11: =F11+J11 | T11: =((U11-O11)/(N11*R11))*100 | U11: =(10^(P11/10))/1000
A12: 2 | B12: 600000000 | C12: 34.938403 | D12: -0.000213 | E12: 0.12731 | F12: 16.938403 | G12: 8.569235 | H12: 3.117743 | J12: 0 | K12: =K11 | L12: =L11 | M12: =M11 | N12: =N11 | O12: =O11 | P12: =C12+J12 | Q12: =D12-L12 | R12: =(E12-M12)*K12 | S12: =F12+J12 | T12: =((U12-O12)/(N12*R12))*100 | U12: =(10^(P12/10))/1000
A13: 3 | B13: 700000000 | C13: 36.204166 | D13: 1.8e-05 | E13: 0.114457 | F13: 18.204166 | G13: 12.823242 | H13: 4.172695 | J13: 0 | K13: =K12 | L13: =L12 | M13: =M12 | N13: =N12 | O13: =O12 | P13: =C13+J13 | Q13: =D13-L13 | R13: =(E13-M13)*K13 | S13: =F13+J13 | T13: =((U13-O13)/(N13*R13))*100 | U13: =(10^(P13/10))/1000
A14: 4 | B14: 800000000 | C14: 36.624177 | D14: -0.000388 | E14: 0.110013 | F14: 18.624177 | G14: 14.716774 | H14: 4.596399 | J14: 0 | K14: =K13 | L14: =L13 | M14: =M13 | N14: =N13 | O14: =O13 | P14: =C14+J14 | Q14: =D14-L14 | R14: =(E14-M14)*K14 | S14: =F14+J14 | T14: =((U14-O14)/(N14*R14))*100 | U14: =(10^(P14/10))/1000
A15: 5 | B15: 900000000 | C15: 37.00573 | D15: -0.000408 | E15: 0.105518 | F15: 19.00573 | G15: 16.772387 | H15: 5.018489 | J15: 0 | K15: =K14 | L15: =L14 | M15: =M14 | N15: =N14 | O15: =O14 | P15: =C15+J15 | Q15: =D15-L15 | R15: =(E15-M15)*K15 | S15: =F15+J15 | T15: =((U15-O15)/(N15*R15))*100 | U15: =(10^(P15/10))/1000
A16: 6 | B16: 1000000000 | C16: 37.236555 | D16: 0.000224 | E16: 0.103911 | F16: 19.236555 | G16: 17.973242 | H16: 5.292435 | J16: 0 | K16: =K15 | L16: =L15 | M16: =M15 | N16: =N15 | O16: =O15 | P16: =C16+J16 | Q16: =D16-L16 | R16: =(E16-M16)*K16 | S16: =F16+J16 | T16: =((U16-O16)/(N16*R16))*100 | U16: =(10^(P16/10))/1000
A17: 7 | B17: 1100000000 | C17: 37.771552 | D17: -3.9e-05 | E17: 0.104119 | F17: 19.771552 | G17: 20.317276 | H17: 5.986254 | J17: 0 | K17: =K16 | L17: =L16 | M17: =M16 | N17: =N16 | O17: =O16 | P17: =C17+J17 | Q17: =D17-L17 | R17: =(E17-M17)*K17 | S17: =F17+J17 | T17: =((U17-O17)/(N17*R17))*100 | U17: =(10^(P17/10))/1000
A18: 8 | B18: 1200000000 | C18: 37.939963 | D18: 3.5e-05 | E18: 0.105259 | F18: 19.939963 | G18: 20.900258 | H18: 6.22295 | J18: 0 | K18: =K17 | L18: =L17 | M18: =M17 | N18: =N17 | O18: =O17 | P18: =C18+J18 | Q18: =D18-L18 | R18: =(E18-M18)*K18 | S18: =F18+J18 | T18: =((U18-O18)/(N18*R18))*100 | U18: =(10^(P18/10))/1000
A19: 9 | B19: 1300000000 | C19: 38.437696 | D19: -0.00016 | E19: 0.110634 | F19: 20.437696 | G19: 22.324407 | H19: 6.97862 | J19: 0 | K19: =K18 | L19: =L18 | M19: =M18 | N19: =N18 | O19: =O18 | P19: =C19+J19 | Q19: =D19-L19 | R19: =(E19-M19)*K19 | S19: =F19+J19 | T19: =((U19-O19)/(N19*R19))*100 | U19: =(10^(P19/10))/1000
A20: 10 | B20: 1400000000 | C20: 39.122293 | D20: -0.000218 | E20: 0.119502 | F20: 21.122293 | G20: 24.228629 | H20: 8.170136 | J20: 0 | K20: =K19 | L20: =L19 | M20: =M19 | N20: =N19 | O20: =O19 | P20: =C20+J20 | Q20: =D20-L20 | R20: =(E20-M20)*K20 | S20: =F20+J20 | T20: =((U20-O20)/(N20*R20))*100 | U20: =(10^(P20/10))/1000
A21: 11 | B21: 1500000000 | C21: 39.792282 | D21: -1.3e-05 | E21: 0.127644 | F21: 21.792282 | G21: 26.496352 | H21: 9.53297 | J21: 0 | K21: =K20 | L21: =L20 | M21: =M20 | N21: =N20 | O21: =O20 | P21: =C21+J21 | Q21: =D21-L21 | R21: =(E21-M21)*K21 | S21: =F21+J21 | T21: =((U21-O21)/(N21*R21))*100 | U21: =(10^(P21/10))/1000
A22: 12 | B22: 1600000000 | C22: 40.269049 | D22: 0.000121 | E22: 0.131258 | F22: 22.269049 | G22: 28.776453 | H22: 10.6391 | J22: 0 | K22: =K21 | L22: =L21 | M22: =M21 | N22: =N21 | O22: =O21 | P22: =C22+J22 | Q22: =D22-L22 | R22: =(E22-M22)*K22 | S22: =F22+J22 | T22: =((U22-O22)/(N22*R22))*100 | U22: =(10^(P22/10))/1000
A23: 13 | B23: 1700000000 | C23: 40.321244 | D23: 0.000146 | E23: 0.134406 | F23: 22.321244 | G23: 28.444407 | H23: 10.767736 | J23: 0 | K23: =K22 | L23: =L22 | M23: =M22 | N23: =N22 | O23: =O22 | P23: =C23+J23 | Q23: =D23-L23 | R23: =(E23-M23)*K23 | S23: =F23+J23 | T23: =((U23-O23)/(N23*R23))*100 | U23: =(10^(P23/10))/1000
... A96: 86 | B96: 9000000000 | C96: 37.121204 | D96: 0.000104 | E96: 0.171275 | F96: 19.121204 | G96: 10.614979 | H96: 5.153715 | J96: 0 | K96: =K95 | L96: =L95 | M96: =M95 | N96: =N95 | O96: =O95 | P96: =C96+J96 | Q96: =D96-L96 | R96: =(E96-M96)*K96 | S96: =F96+J96 | T96: =((U96-O96)/(N96*R96))*100 | U96: =(10^(P96/10))/1000

Sheet NiPA-62-F_UG_1__2026-03-24_11-4
A1: Мощность на УБМ, dBm | B1: 27
A2: Gate start, ms | B2: 50
A3: Gate lenght, ms | B3: 50
A4: T, ms | B4: 100
A5: Точность подстройки, dBm | B5: 0.1
A6: Iпот(покоя), mA | B6: 350
A7: Uп, В | B7: 28
A8: Uсм, ¬
A9: — калибровкой
A10: є | B10: f, MHz | C10: P, dBm | D10: IG, mA | E10: ID, A | F10: Gain, dB | G10: ѕƒ, % | H10: Pвых, W | J10: Потери | K10: Q | L10: Ig_пок, мА | M10: Iпок, А | N10: Uп, В | O10: Pвх, Вт | P10: =C10 | Q10: =D10 | R10: =E10 | S10: =F10 | T10: =G10 | U10: =H10
A11: 1 | B11: 500000000 | C11: 39.382375 | D11: -0.000122 | E11: 0.517985 | F11: 12.382375 | G11: 56.352756 | H11: 8.674361 | J11: 0 | K11: 1 | L11: 0 | M11: 0 | N11: =B7 | O11: =(10^(B1/10))/1000 | P11: 39.382375 | Q11: -0.000122 | R11: 0.517985 | S11: 12.382375 | T11: 56.352756 | U11: 8.674361
A12: 2 | B12: 600000000 | C12: 39.366771 | D12: -0.00012 | E12: 0.493286 | F12: 12.366771 | G12: 58.949217 | H12: 8.643251 | J12: 0 | K12: =K11 | L12: =L11 | M12: =M11 | N12: =N11 | O12: =O11 | P12: 39.366771 | Q12: -0.00012 | R12: 0.493286 | S12: 12.366771 | T12: 58.949217 | U12: 8.643251
A13: 3 | B13: 700000000 | C13: 39.289049 | D13: 0.000318 | E13: 0.499063 | F13: 12.289049 | G13: 57.169686 | H13: 8.489945 | J13: 0 | K13: =K12 | L13: =L12 | M13: =M12 | N13: =N12 | O13: =O12 | P13: 39.289049 | Q13: 0.000318 | R13: 0.499063 | S13: 12.289049 | T13: 57.169686 | U13: 8.489945
A14: 4 | B14: 800000000 | C14: 39.619725 | D14: 6.8e-05 | E14: 0.538351 | F14: 12.619725 | G14: 57.453453 | H14: 9.161624 | J14: 0 | K14: =K13 | L14: =L13 | M14: =M13 | N14: =N13 | O14: =O13 | P14: 39.619725 | Q14: 6.8e-05 | R14: 0.538351 | S14: 12.619725 | T14: 57.453453 | U14: 9.161624
A15: 5 | B15: 900000000 | C15: 39.806788 | D15: 0.00014 | E15: 0.549765 | F15: 12.806788 | G15: 58.880179 | H15: 9.564864 | J15: 0 | K15: =K14 | L15: =L14 | M15: =M14 | N15: =N14 | O15: =O14 | P15: 39.806788 | Q15: 0.00014 | R15: 0.549765 | S15: 12.806788 | T15: 58.880179 | U15: 9.564864
A16: 6 | B16: 1000000000 | C16: 39.812635 | D16: -0.000331 | E16: 0.573374 | F16: 12.812635 | G16: 56.536021 | H16: 9.57775 | J16: 0 | K16: =K15 | L16: =L15 | M16: =M15 | N16: =N15 | O16: =O15 | P16: 39.812635 | Q16: -0.000331 | R16: 0.573374 | S16: 12.812635 | T16: 56.536021 | U16: 9.57775
A17: 7 | B17: 1100000000 | C17: 39.725522 | D17: 2.7e-05 | E17: 0.572431 | F17: 12.725522 | G17: 55.442489 | H17: 9.387549 | J17: 0 | K17: =K16 | L17: =L16 | M17: =M16 | N17: =N16 | O17: =O16 | P17: 39.725522 | Q17: 2.7e-05 | R17: 0.572431 | S17: 12.725522 | T17: 55.442489 | U17: 9.387549
A18: 8 | B18: 1200000000 | C18: 39.374186 | D18: -0.000115 | E18: 0.591105 | F18: 12.374186 | G18: 49.283172 | H18: 8.658021 | J18: 0 | K18: =K17 | L18: =L17 | M18: =M17 | N18: =N17 | O18: =O17 | P18: 39.374186 | Q18: -0.000115 | R18: 0.591105 | S18: 12.374186 | T18: 49.283172 | U18: 8.658021
A19: 9 | B19: 1300000000 | C19: 39.423717 | D19: -0.000419 | E19: 0.630442 | F19: 12.423717 | G19: 46.770689 | H19: 8.757329 | J19: 0 | K19: =K18 | L19: =L18 | M19: =M18 | N19: =N18 | O19: =O18 | P19: 39.423717 | Q19: -0.000419 | R19: 0.630442 | S19: 12.423717 | T19: 46.770689 | U19: 8.757329
A20: 10 | B20: 1400000000 | C20: 39.418516 | D20: -0.000443 | E20: 0.643107 | F20: 12.418516 | G20: 45.791436 | H20: 8.746848 | J20: 0 | K20: =K19 | L20: =L19 | M20: =M19 | N20: =N19 | O20: =O19 | P20: 39.418516 | Q20: -0.000443 | R20: 0.643107 | S20: 12.418516 | T20: 45.791436 | U20: 8.746848
A21: 11 | B21: 1500000000 | C21: 39.348883 | D21: -0.00024 | E21: 0.655046 | F21: 12.348883 | G21: 44.1983 | H21: 8.607724 | J21: 0 | K21: =K20 | L21: =L20 | M21: =M20 | N21: =N20 | O21: =O20 | P21: 39.348883 | Q21: -0.00024 | R21: 0.655046 | S21: 12.348883 | T21: 44.1983 | U21: 8.607724
A22: 12 | B22: 1600000000 | C22: 39.248171 | D22: -0.000295 | E22: 0.674156 | F22: 12.248171 | G22: 41.900098 | H22: 8.410408 | J22: 0 | K22: =K21 | L22: =L21 | M22: =M21 | N22: =N21 | O22: =O21 | P22: 39.248171 | Q22: -0.000295 | R22: 0.674156 | S22: 12.248171 | T22: 41.900098 | U22: 8.410408
A23: 13 | B23: 1700000000 | C23: 39.241689 | D23: -0.00029 | E23: 0.666402 | F23: 12.241689 | G23: 42.320448 | H23: 8.397865 | J23: 0 | K23: =K22 | L23: =L22 | M23: =M22 | N23: =N22 | O23: =O22 | P23: 39.241689 | Q23: -0.00029 | R23: 0.666402 | S23: 12.241689 | T23: 42.320448 | U23: 8.397865
... A46: 36 | B46: 4000000000 | C46: 38.588967 | D46: 0.000342 | E46: 0.763505 | F46: 11.588967 | G46: 31.456411 | H46: 7.225979 | J46: 0 | K46: =K45 | L46: =L45 | M46: =M45 | N46: =N45 | O46: =O45 | P46: 38.588967 | Q46: 0.000342 | R46: 0.763505 | S46: 11.588967 | T46: 31.456411 | U46: 7.225979
A47: 37 | B47: 4100000000 | C47: 41.14297 | D47: -0.000353 | E47: 0.179271 | F47: 23.14297 | G47: 25.793955 | H47: 13.010589 | J47: 0 | K47: =K46 | L47: =L46 | M47: =M46 | N47: =N46 | O47: =O46 | P47: =C47+J47 | Q47: =D47-L47 | R47: =(E47-M47)*K47 | S47: =F47+J47 | T47: =((U47-O47)/(N47*R47))*100 | U47: =(10^(P47/10))/1000
A48: 38 | B48: 4200000000 | C48: 40.932515 | D48: -0.000425 | E48: 0.175532 | F48: 22.932515 | G48: 25.09119 | H48: 12.395142 | J48: 0 | K48: =K47 | L48: =L47 | M48: =M47 | N48: =N47 | O48: =O47 | P48: =C48+J48 | Q48: =D48-L48 | R48: =(E48-M48)*K48 | S48: =F48+J48 | T48: =((U48-O48)/(N48*R48))*100 | U48: =(10^(P48/10))/1000
A49: 39 | B49: 4300000000 | C49: 40.857652 | D49: -0.000347 | E49: 0.174821 | F49: 22.857652 | G49: 24.760419 | H49: 12.183307 | J49: 0 | K49: =K48 | L49: =L48 | M49: =M48 | N49: =N48 | O49: =O48 | P49: =C49+J49 | Q49: =D49-L49 | R49: =(E49-M49)*K49 | S49: =F49+J49 | T49: =((U49-O49)/(N49*R49))*100 | U49: =(10^(P49/10))/1000
A50: 40 | B50: 4400000000 | C50: 40.95253 | D50: -0.000276 | E50: 0.175814 | F50: 22.95253 | G50: 25.167183 | H50: 12.452397 | J50: 0 | K50: =K49 | L50: =L49 | M50: =M49 | N50: =N49 | O50: =O49 | P50: =C50+J50 | Q50: =D50-L50 | R50: =(E50-M50)*K50 | S50: =F50+J50 | T50: =((U50-O50)/(N50*R50))*100 | U50: =(10^(P50/10))/1000
A51: 41 | B51: 4500000000 | C51: 40.890987 | D51: -0.000261 | E51: 0.173767 | F51: 22.890987 | G51: 25.103556 | H51: 12.277183 | J51: 0 | K51: =K50 | L51: =L50 | M51: =M50 | N51: =N50 | O51: =O50 | P51: =C51+J51 | Q51: =D51-L51 | R51: =(E51-M51)*K51 | S51: =F51+J51 | T51: =((U51-O51)/(N51*R51))*100 | U51: =(10^(P51/10))/1000
A52: 42 | B52: 4600000000 | C52: 40.740238 | D52: -0.000333 | E52: 0.174226 | F52: 22.740238 | G52: 24.178826 | H52: 11.858336 | J52: 0 | K52: =K51 | L52: =L51 | M52: =M51 | N52: =N51 | O52: =O51 | P52: =C52+J52 | Q52: =D52-L52 | R52: =(E52-M52)*K52 | S52: =F52+J52 | T52: =((U52-O52)/(N52*R52))*100 | U52: =(10^(P52/10))/1000
A53: 43 | B53: 4700000000 | C53: 40.590238 | D53: -0.000432 | E53: 0.169685 | F53: 22.590238 | G53: 23.978532 | H53: 11.455756 | J53: 0 | K53: =K52 | L53: =L52 | M53: =M52 | N53: =N52 | O53: =O52 | P53: =C53+J53 | Q53: =D53-L53 | R53: =(E53-M53)*K53 | S53: =F53+J53 | T53: =((U53-O53)/(N53*R53))*100 | U53: =(10^(P53/10))/1000
A54: 44 | B54: 4800000000 | C54: 40.312879 | D54: -0.00012 | E54: 0.164108 | F54: 22.312879 | G54: 23.251131 | H54: 10.747017 | J54: 0 | K54: =K53 | L54: =L53 | M54: =M53 | N54: =N53 | O54: =O53 | P54: =C54+J54 | Q54: =D54-L54 | R54: =(E54-M54)*K54 | S54: =F54+J54 | T54: =((U54-O54)/(N54*R54))*100 | U54: =(10^(P54/10))/1000
A55: 45 | B55: 4900000000 | C55: 40.164663 | D55: -0.000235 | E55: 0.16199 | F55: 22.164663 | G55: 22.760012 | H55: 10.38643 | J55: 0 | K55: =K54 | L55: =L54 | M55: =M54 | N55: =N54 | O55: =O54 | P55: =C55+J55 | Q55: =D55-L55 | R55: =(E55-M55)*K55 | S55: =F55+J55 | T55: =((U55-O55)/(N55*R55))*100 | U55: =(10^(P55/10))/1000
A56: 46 | B56: 5000000000 | C56: 40.139931 | D56: -0.000525 | E56: 0.160708 | F56: 22.139931 | G56: 22.810591 | H56: 10.327451 | J56: 0 | K56: =K55 | L56: =L55 | M56: =M55 | N56: =N55 | O56: =O55 | P56: =C56+J56 | Q56: =D56-L56 | R56: =(E56-M56)*K56 | S56: =F56+J56 | T56: =((U56-O56)/(N56*R56))*100 | U56: =(10^(P56/10))/1000
A57: 47 | B57: 5100000000 | C57: 39.991157 | D57: -1.1e-05 | E57: 0.16469 | F57: 21.991157 | G57: 21.504826 | H57: 9.979658 | J57: 0 | K57: =K56 | L57: =L56 | M57: =M56 | N57: =N56 | O57: =O56 | P57: =C57+J57 | Q57: =D57-L57 | R57: =(E57-M57)*K57 | S57: =F57+J57 | T57: =((U57-O57)/(N57*R57))*100 | U57: =(10^(P57/10))/1000
A58: 48 | B58: 5200000000 | C58: 40.056314 | D58: -0.000364 | E58: 0.173553 | F58: 22.056314 | G58: 20.71706 | H58: 10.130513 | J58: 0 | K58: =K57 | L58: =L57 | M58: =M57 | N58: =N57 | O58: =O57 | P58: =C58+J58 | Q58: =D58-L58 | R58: =(E58-M58)*K58 | S58: =F58+J58 | T58: =((U58-O58)/(N58*R58))*100 | U58: =(10^(P58/10))/1000
... A96: 86 | B96: 9000000000 | C96: 37.121204 | D96: 0.000104 | E96: 0.171275 | F96: 19.121204 | G96: 10.614979 | H96: 5.153715 | J96: 0 | K96: =K95 | L96: =L95 | M96: =M95 | N96: =N95 | O96: =O95 | P96: =C96+J96 | Q96: =D96-L96 | R96: =(E96-M96)*K96 | S96: =F96+J96 | T96: =((U96-O96)/(N96*R96))*100 | U96: =(10^(P96/10))/1000

Sheet NiPA-62-F_UG_2__2026-03-24_11-5
A1: Мощность на УБМ, dBm | B1: 27
A2: Gate start, ms | B2: 50
A3: Gate lenght, ms | B3: 50
A4: T, ms | B4: 100
A5: Точность подстройки, dBm | B5: 0.1
A6: Iпот(покоя), mA | B6: 350
A7: Uп, В | B7: 28
A8: Uсм, ¬
A9: — калибровкой
A10: є | B10: f, MHz | C10: P, dBm | D10: IG, mA | E10: ID, A | F10: Gain, dB | G10: ѕƒ, % | H10: Pвых, W | J10: Потери | K10: Q | L10: Ig_пок, мА | M10: Iпок, А | N10: Uп, В | O10: Pвх, Вт | P10: =C10 | Q10: =D10 | R10: =E10 | S10: =F10 | T10: =G10 | U10: =H10
A11: 1 | B11: 500000000 | C11: 39.405177 | D11: 0.000159 | E11: 0.519489 | F11: 12.405177 | G11: 56.503554 | H11: 8.720023 | J11: 0 | K11: 1 | L11: 0 | M11: 0 | N11: =B7 | O11: =(10^(B1/10))/1000 | P11: 39.405177 | Q11: 0.000159 | R11: 0.519489 | S11: 12.405177 | T11: 56.503554 | U11: 8.720023
A12: 2 | B12: 600000000 | C12: 39.388719 | D12: 8.1e-05 | E12: 0.493501 | F12: 12.388719 | G12: 59.240388 | H12: 8.687041 | J12: 0 | K12: =K11 | L12: =L11 | M12: =M11 | N12: =N11 | O12: =O11 | P12: 39.388719 | Q12: 8.1e-05 | R12: 0.493501 | S12: 12.388719 | T12: 59.240388 | U12: 8.687041
A13: 3 | B13: 700000000 | C13: 39.290105 | D13: -0.000446 | E13: 0.497181 | F13: 12.290105 | G13: 57.400913 | H13: 8.492011 | J13: 0 | K13: =K12 | L13: =L12 | M13: =M12 | N13: =N12 | O13: =O12 | P13: 39.290105 | Q13: -0.000446 | R13: 0.497181 | S13: 12.290105 | T13: 57.400913 | U13: 8.492011
A14: 4 | B14: 800000000 | C14: 39.617169 | D14: -0.000398 | E14: 0.536311 | F14: 12.617169 | G14: 57.636144 | H14: 9.156235 | J14: 0 | K14: =K13 | L14: =L13 | M14: =M13 | N14: =N13 | O14: =O13 | P14: 39.617169 | Q14: -0.000398 | R14: 0.536311 | S14: 12.617169 | T14: 57.636144 | U14: 9.156235
A15: 5 | B15: 900000000 | C15: 39.812192 | D15: -0.000408 | E15: 0.548018 | F15: 12.812192 | G15: 59.14551 | H15: 9.576773 | J15: 0 | K15: =K14 | L15: =L14 | M15: =M14 | N15: =N14 | O15: =O14 | P15: 39.812192 | Q15: -0.000408 | R15: 0.548018 | S15: 12.812192 | T15: 59.14551 | U15: 9.576773
A16: 6 | B16: 1000000000 | C16: 39.810115 | D16: -0.000432 | E16: 0.570779 | F16: 12.810115 | G16: 56.758355 | H16: 9.572195 | J16: 0 | K16: =K15 | L16: =L15 | M16: =M15 | N16: =N15 | O16: =O15 | P16: 39.810115 | Q16: -0.000432 | R16: 0.570779 | S16: 12.810115 | T16: 56.758355 | U16: 9.572195
A17: 7 | B17: 1100000000 | C17: 39.734777 | D17: 0.000405 | E17: 0.568346 | F17: 12.734777 | G17: 55.966878 | H17: 9.407576 | J17: 0 | K17: =K16 | L17: =L16 | M17: =M16 | N17: =N16 | O17: =O16 | P17: 39.734777 | Q17: 0.000405 | R17: 0.568346 | S17: 12.734777 | T17: 55.966878 | U17: 9.407576
A18: 8 | B18: 1200000000 | C18: 39.376859 | D18: 0.000183 | E18: 0.586651 | F18: 12.376859 | G18: 49.68979 | H18: 8.66335 | J18: 0 | K18: =K17 | L18: =L17 | M18: =M17 | N18: =N17 | O18: =O17 | P18: 39.376859 | Q18: 0.000183 | R18: 0.586651 | S18: 12.376859 | T18: 49.68979 | U18: 8.66335
A19: 9 | B19: 1300000000 | C19: 39.430832 | D19: -0.000279 | E19: 0.626152 | F19: 12.430832 | G19: 47.173048 | H19: 8.771689 | J19: 0 | K19: =K18 | L19: =L18 | M19: =M18 | N19: =N18 | O19: =O18 | P19: 39.430832 | Q19: -0.000279 | R19: 0.626152 | S19: 12.430832 | T19: 47.173048 | U19: 8.771689
A20: 10 | B20: 1400000000 | C20: 39.467568 | D20: -0.000146 | E20: 0.640861 | F20: 12.467568 | G20: 46.5056 | H20: 8.846202 | J20: 0 | K20: =K19 | L20: =L19 | M20: =M19 | N20: =N19 | O20: =O19 | P20: 39.467568 | Q20: -0.000146 | R20: 0.640861 | S20: 12.467568 | T20: 46.5056 | U20: 8.846202
A21: 11 | B21: 1500000000 | C21: 39.471317 | D21: -0.000235 | E21: 0.65585 | F21: 12.471317 | G21: 45.484336 | H21: 8.85384 | J21: 0 | K21: =K20 | L21: =L20 | M21: =M20 | N21: =N20 | O21: =O20 | P21: 39.471317 | Q21: -0.000235 | R21: 0.65585 | S21: 12.471317 | T21: 45.484336 | U21: 8.85384
A22: 12 | B22: 1600000000 | C22: 39.32506 | D22: -0.000176 | E22: 0.669135 | F22: 12.32506 | G22: 43.016339 | H22: 8.560636 | J22: 0 | K22: =K21 | L22: =L21 | M22: =M21 | N22: =N21 | O22: =O21 | P22: 39.32506 | Q22: -0.000176 | R22: 0.669135 | S22: 12.32506 | T22: 43.016339 | U22: 8.560636
A23: 13 | B23: 1700000000 | C23: 39.246492 | D23: 0.000227 | E23: 0.662736 | F23: 12.246492 | G23: 42.604608 | H23: 8.407158 | J23: 0 | K23: =K22 | L23: =L22 | M23: =M22 | N23: =N22 | O23: =O22 | P23: 39.246492 | Q23: 0.000227 | R23: 0.662736 | S23: 12.246492 | T23: 42.604608 | U23: 8.407158
... A46: 36 | B46: 4000000000 | C46: 38.624474 | D46: 0.000163 | E46: 0.763983 | F46: 11.624474 | G46: 31.714039 | H46: 7.2853 | J46: 0 | K46: =K45 | L46: =L45 | M46: =M45 | N46: =N45 | O46: =O45 | P46: 38.624474 | Q46: 0.000163 | R46: 0.763983 | S46: 11.624474 | T46: 31.714039 | U46: 7.2853
A47: 37 | B47: 4100000000 | C47: 41.14297 | D47: -0.000353 | E47: 0.179271 | F47: 23.14297 | G47: 25.793955 | H47: 13.010589 | J47: 0 | K47: =K46 | L47: =L46 | M47: =M46 | N47: =N46 | O47: =O46 | P47: =C47+J47 | Q47: =D47-L47 | R47: =(E47-M47)*K47 | S47: =F47+J47 | T47: =((U47-O47)/(N47*R47))*100 | U47: =(10^(P47/10))/1000
A48: 38 | B48: 4200000000 | C48: 40.932515 | D48: -0.000425 | E48: 0.175532 | F48: 22.932515 | G48: 25.09119 | H48: 12.395142 | J48: 0 | K48: =K47 | L48: =L47 | M48: =M47 | N48: =N47 | O48: =O47 | P48: =C48+J48 | Q48: =D48-L48 | R48: =(E48-M48)*K48 | S48: =F48+J48 | T48: =((U48-O48)/(N48*R48))*100 | U48: =(10^(P48/10))/1000
A49: 39 | B49: 4300000000 | C49: 40.857652 | D49: -0.000347 | E49: 0.174821 | F49: 22.857652 | G49: 24.760419 | H49: 12.183307 | J49: 0 | K49: =K48 | L49: =L48 | M49: =M48 | N49: =N48 | O49: =O48 | P49: =C49+J49 | Q49: =D49-L49 | R49: =(E49-M49)*K49 | S49: =F49+J49 | T49: =((U49-O49)/(N49*R49))*100 | U49: =(10^(P49/10))/1000
A50: 40 | B50: 4400000000 | C50: 40.95253 | D50: -0.000276 | E50: 0.175814 | F50: 22.95253 | G50: 25.167183 | H50: 12.452397 | J50: 0 | K50: =K49 | L50: =L49 | M50: =M49 | N50: =N49 | O50: =O49 | P50: =C50+J50 | Q50: =D50-L50 | R50: =(E50-M50)*K50 | S50: =F50+J50 | T50: =((U50-O50)/(N50*R50))*100 | U50: =(10^(P50/10))/1000
A51: 41 | B51: 4500000000 | C51: 40.890987 | D51: -0.000261 | E51: 0.173767 | F51: 22.890987 | G51: 25.103556 | H51: 12.277183 | J51: 0 | K51: =K50 | L51: =L50 | M51: =M50 | N51: =N50 | O51: =O50 | P51: =C51+J51 | Q51: =D51-L51 | R51: =(E51-M51)*K51 | S51: =F51+J51 | T51: =((U51-O51)/(N51*R51))*100 | U51: =(10^(P51/10))/1000
A52: 42 | B52: 4600000000 | C52: 40.740238 | D52: -0.000333 | E52: 0.174226 | F52: 22.740238 | G52: 24.178826 | H52: 11.858336 | J52: 0 | K52: =K51 | L52: =L51 | M52: =M51 | N52: =N51 | O52: =O51 | P52: =C52+J52 | Q52: =D52-L52 | R52: =(E52-M52)*K52 | S52: =F52+J52 | T52: =((U52-O52)/(N52*R52))*100 | U52: =(10^(P52/10))/1000
A53: 43 | B53: 4700000000 | C53: 40.590238 | D53: -0.000432 | E53: 0.169685 | F53: 22.590238 | G53: 23.978532 | H53: 11.455756 | J53: 0 | K53: =K52 | L53: =L52 | M53: =M52 | N53: =N52 | O53: =O52 | P53: =C53+J53 | Q53: =D53-L53 | R53: =(E53-M53)*K53 | S53: =F53+J53 | T53: =((U53-O53)/(N53*R53))*100 | U53: =(10^(P53/10))/1000
A54: 44 | B54: 4800000000 | C54: 40.312879 | D54: -0.00012 | E54: 0.164108 | F54: 22.312879 | G54: 23.251131 | H54: 10.747017 | J54: 0 | K54: =K53 | L54: =L53 | M54: =M53 | N54: =N53 | O54: =O53 | P54: =C54+J54 | Q54: =D54-L54 | R54: =(E54-M54)*K54 | S54: =F54+J54 | T54: =((U54-O54)/(N54*R54))*100 | U54: =(10^(P54/10))/1000
A55: 45 | B55: 4900000000 | C55: 40.164663 | D55: -0.000235 | E55: 0.16199 | F55: 22.164663 | G55: 22.760012 | H55: 10.38643 | J55: 0 | K55: =K54 | L55: =L54 | M55: =M54 | N55: =N54 | O55: =O54 | P55: =C55+J55 | Q55: =D55-L55 | R55: =(E55-M55)*K55 | S55: =F55+J55 | T55: =((U55-O55)/(N55*R55))*100 | U55: =(10^(P55/10))/1000
A56: 46 | B56: 5000000000 | C56: 40.139931 | D56: -0.000525 | E56: 0.160708 | F56: 22.139931 | G56: 22.810591 | H56: 10.327451 | J56: 0 | K56: =K55 | L56: =L55 | M56: =M55 | N56: =N55 | O56: =O55 | P56: =C56+J56 | Q56: =D56-L56 | R56: =(E56-M56)*K56 | S56: =F56+J56 | T56: =((U56-O56)/(N56*R56))*100 | U56: =(10^(P56/10))/1000
A57: 47 | B57: 5100000000 | C57: 39.991157 | D57: -1.1e-05 | E57: 0.16469 | F57: 21.991157 | G57: 21.504826 | H57: 9.979658 | J57: 0 | K57: =K56 | L57: =L56 | M57: =M56 | N57: =N56 | O57: =O56 | P57: =C57+J57 | Q57: =D57-L57 | R57: =(E57-M57)*K57 | S57: =F57+J57 | T57: =((U57-O57)/(N57*R57))*100 | U57: =(10^(P57/10))/1000
